[  {
    "type": "part",
    "name": "bridge_covered",
    "xsize": 16,
    "zsize": 16,
    "meta": [
      {
        "key": "support",
        "char": "v"
      }
    ],
    "slices": [
      [
        "                ",
        "                ",
        "                ",
        "vvvvvvvvvvvvvvvv",
        "SSSSSSSSSSSSSSSS",
        "SSSSSSSSSSSSSSSS",
        "SSSSSSSSSSSSSSSS",
        "SSSSSSSSSSSSSSSS",
        "SSSSSSSSSSSSSSSS",
        "SSSSSSSSSSSSSSSS",
        "SSSSSSSSSSSSSSSS",
        "SSSSSSSSSSSSSSSS",
        "vvvvvvvvvvvvvvvv",
        "                ",
        "                ",
        "                "
      ],
      [
        "                ",
        "                ",
        "                ",
        "wwwwvwwwwwwwvwww",
        "    T       T   ",
        "                ",
        "                ",
        "                ",
        "                ",
        "                ",
        "                ",
        "    T       T   ",
        "wwwwvwwwwwwwvwww",
        "                ",
        "                ",
        "                "
      ],
      [
        "                ",
        "                ",
        "                ",
        "    w       w   ",
        "                ",
        "                ",
        "                ",
        "                ",
        "                ",
        "                ",
        "                ",
        "                ",
        "    w       w   ",
        "                ",
        "                ",
        "                "
      ],
      [
        "                ",
        "                ",
        "                ",
        "    w       w   ",
        "                ",
        "                ",
        "                ",
        "                ",
        "                ",
        "                ",
        "                ",
        "                ",
        "    w       w   ",
        "                ",
        "                ",
        "                "
      ],
      [
        "                ",
        "                ",
        "                ",
        "    w       w   ",
        "                ",
        "                ",
        "                ",
        "                ",
        "                ",
        "                ",
        "                ",
        "                ",
        "    w       w   ",
        "                ",
        "                ",
        "                "
      ],
      [
        "                ",
        "                ",
        "                ",
        "    w       w   ",
        "                ",
        "                ",
        "                ",
        "                ",
        "                ",
        "                ",
        "                ",
        "                ",
        "    w       w   ",
        "                ",
        "                ",
        "                "
      ],
      [
        "                ",
        "                ",
        "                ",
        "vvvvvvvvvvvvvvvv",
        "SSSSSSSSSSSSSSSS",
        "SSSSSSSSSSSSSSSS",
        "SSSSSSSSSSSSSSSS",
        "SSSSSSSSSSSSSSSS",
        "SSSSSSSSSSSSSSSS",
        "SSSSSSSSSSSSSSSS",
        "SSSSSSSSSSSSSSSS",
        "SSSSSSSSSSSSSSSS",
        "vvvvvvvvvvvvvvvv",
        "                ",
        "                ",
        "                "
      ]
    ]
  }]