[  {
    "type": "part",
    "name": "building1_6",
    "xsize": 16,
    "zsize": 16,
    "slices": [
      [
        "################",
        "################",
        "################",
        "################",
        "################",
        "################",
        "################",
        "################",
        "################",
        "#######l########",
        "################",
        "################",
        "################",
        "################",
        "################",
        "################"
      ],
      [
        "#aa@aaaaaaaa@aa#",
        "a              a",
        "a              a",
        "@              @",
        "a              a",
        "a              a",
        "a    ## ##     a",
        "a    #   ######a",
        "a              a",
        "a    # l #     a",
        "a    #####     a",
        "a      F#      a",
        "@       #      @",
        "a              a",
        "a       #      a",
        "#aa@aaaaaaaa@aa#"
      ],
      [
        "#aa@aaaaaaaa@aa#",
        "a              a",
        "a              a",
        "@              @",
        "a              a",
        "a              a",
        "a    ## ##     a",
        "a    #   ###:##a",
        "a          T T a",
        "a    # l #     a",
        "a    #####     a",
        "a       #      a",
        "@       #      @",
        "a              a",
        "a       #      a",
        "#aa@aaaaaaaa@aa#"
      ],
      [
        "#aa@aaaaaaaa@aa#",
        "a              a",
        "a              a",
        "@              @",
        "a              a",
        "a              a",
        "a    #####     a",
        "a    #   ######a",
        "a    #   #     a",
        "a    # l #     a",
        "a    #####     a",
        "a       #      a",
        "@       #      @",
        "a       #      a",
        "a       #      a",
        "#aa@aaaaaaaa@aa#"
      ],
      [
        "################",
        "################",
        "################",
        "################",
        "################",
        "################",
        "################",
        "################",
        "################",
        "#######l########",
        "################",
        "################",
        "################",
        "################",
        "################",
        "################"
      ],
      [
        "################",
        "################",
        "################",
        "################",
        "################",
        "################",
        "################",
        "################",
        "################",
        "#######l########",
        "################",
        "################",
        "################",
        "################",
        "################",
        "################"
      ]
    ]
  }]