[  {
    "type": "part",
    "name": "building1_3",
    "xsize": 16,
    "zsize": 16,
    "slices": [
      [
        "################",
        "################",
        "################",
        "################",
        "################",
        "################",
        "################",
        "################",
        "################",
        "#######l########",
        "################",
        "################",
        "################",
        "################",
        "################",
        "################"
      ],
      [
        "#aa@aaaaaaaa@aa#",
        "aWWWWWWWWWWWWWWa",
        "aWWWWWWWWWWWWWWa",
        "@WWWWWWWWWWWWWW@",
        "aWWWWWWWWWWWWWWa",
        "aaaaaaaaaaaaaaaa",
        "a              a",
        "a              a",
        "aL             a",
        "aF     l       a",
        "aF    ###::::::a",
        "a      :       a",
        "@      :   T   @",
        "a      :       a",
        "a      :       a",
        "#aa@aaaaaaaa@aa#"
      ],
      [
        "#aa@aaaaaaaa@aa#",
        "aWWWWWWWWWWWWWWa",
        "aWWWWWWWWWWWWWWa",
        "@WWWWWWWWWWWWWW@",
        "aWWWWWWWWWWWWWWa",
        "aaaaaaaaaaaaaaaa",
        "a              a",
        "a              a",
        "aL             a",
        "a      l       a",
        "a     ###::::::a",
        "a      :       a",
        "@      :       @",
        "a      :       a",
        "a      :       a",
        "#aa@aaaaaaaa@aa#"
      ],
      [
        "#aa@aaaaaaaa@aa#",
        "aWWWWWWWWWWWWWWa",
        "aWWWWWWWWWWWWWWa",
        "@WWWWWWWWWWWWWW@",
        "aWWWWWWWWWWWWWWa",
        "aaaaaaaaaaaaaaaa",
        "a              a",
        "a              a",
        "aL             a",
        "a      l       a",
        "a     ###::::::a",
        "a      :       a",
        "@      :       @",
        "a      :       a",
        "a      :       a",
        "#aa@aaaaaaaa@aa#"
      ],
      [
        "################",
        "################",
        "################",
        "################",
        "################",
        "################",
        "################",
        "################",
        "################",
        "#######l########",
        "################",
        "################",
        "##1#1###########",
        "################",
        "################",
        "################"
      ],
      [
        "################",
        "################",
        "################",
        "################",
        "################",
        "################",
        "################",
        "################",
        "################",
        "#######l########",
        "################",
        "################",
        "################",
        "################",
        "################",
        "################"
      ]
    ]
  }]