[ {
    "type": "part",
    "name": "building3_2",
    "xsize": 16,
    "zsize": 16,
    "slices": [
      [
        "##   ######   ##",
        "################",
        " ############## ",
        " ############## ",
        " ############## ",
        "#######1########",
        "################",
        "################",
        "################",
        "#######l########",
        "#####1##########",
        " ############## ",
        " ############## ",
        " ############## ",
        "################",
        "##   ######   ##"
      ],
      [
        "##   ######   ##",
        "##aaa#F   #aaa##",
        " a            a ",
        " a   F        a ",
        " a            a ",
        "##  #######   ##",
        "#   :     :    #",
        "#   :  F       #",
        "#   :          #",
        "#   :  l  :    #",
        "##  #######   ##",
        " a            a ",
        " a   FF       a ",
        " a            a ",
        "##aaa#    #aaa##",
        "##   ######   ##"
      ],
      [
        "##   ######   ##",
        "##aaa#    #aaa##",
        " a            a ",
        " a            a ",
        " a            a ",
        "##  #######   ##",
        "#   :  T  :    #",
        "#   :          #",
        "#   :          #",
        "#   :  l  :    #",
        "##  #######   ##",
        " a            a ",
        " a            a ",
        " a            a ",
        "##aaa#    #aaa##",
        "##   ######   ##"
      ],
      [
        "##   ######   ##",
        "##aaa#    #aaa##",
        " a            a ",
        " a            a ",
        " a            a ",
        "##  #######   ##",
        "#   :     :    #",
        "#   :          #",
        "#   :          #",
        "#   :  l  :    #",
        "##  #######   ##",
        " a            a ",
        " a            a ",
        " a            a ",
        "##aaa#    #aaa##",
        "##   ######   ##"
      ],
      [
        "##   ######   ##",
        "################",
        " ############## ",
        " ############## ",
        " ############## ",
        "################",
        "################",
        "################",
        "################",
        "#######l########",
        "################",
        " ############## ",
        " ############## ",
        " ############## ",
        "################",
        "##   ######   ##"
      ],
      [
        "##   ######   ##",
        "################",
        " ############## ",
        " ############## ",
        " ############## ",
        "################",
        "################",
        "################",
        "################",
        "#######l########",
        "################",
        " ############## ",
        " ############## ",
        " ############## ",
        "################",
        "##   ######   ##"
      ]
    ]
  }]