[  {
    "type": "part",
    "name": "building5_3",
    "xsize": 16,
    "zsize": 16,
    "slices": [
      [
        "################",
        "################",
        "################",
        "################",
        "################",
        "################",
        "################",
        "################",
        "################",
        "#######l########",
        "################",
        "################",
        "################",
        "################",
        "################",
        "################"
      ],
      [
        "##___##  ###___##",
        "###### aa ######",
        "_#F           #_",
        "_#     F      #_",
        "_#           F#_",
        "#######  #######",
        "#              #",
        "# .    F     . #",
        "# .          . #",
        "#      l       #",
        "##    ###     ##",
        "_#            #_",
        "_#            #_",
        "_#            #_",
        "######    ######",
        "##___######___##"
      ],
      [
        "##   ######   ##",
        "##aaa#    #aaa##",
        " a            a ",
        " a            a ",
        " a            a ",
        "##aaaa#  #aaaa##",
        "#              #",
        "# -          - #",
        "# -          - #",
        "#      l       #",
        "##    ###     ##",
        " a            a ",
        " a            a ",
        " a            a ",
        "##aaa#    #aaa##",
        "##   ######   ##"
      ],
      [
        "##   ######   ##",
        "##aaa#    #aaa##",
        " a            a ",
        " a            a ",
        " a    T  T    a ",
        "##aaaa####aaaa##",
        "#              #",
        "#              #",
        "#              #",
        "#      l       #",
        "##T   ###    T##",
        " a            a ",
        " a            a ",
        " a            a ",
        "##aaa#    #aaa##",
        "##   ######   ##"
      ],
      [
        "##   ######   ##",
        "##aaa#    #aaa##",
        " a            a ",
        " a            a ",
        " a            a ",
        "################",
        "#              #",
        "#              #",
        "#              #",
        "#      l       #",
        "##    ###     ##",
        " a            a ",
        " a            a ",
        " a            a ",
        "##aaa#    #aaa##",
        "##   ######   ##"
      ],
      [
        "##===######===##",
        "################",
        "=##############=",
        "=##############=",
        "=##############=",
        "################",
        "################",
        "################",
        "################",
        "#######l########",
        "################",
        "=##############=",
        "=##############=",
        "=##############=",
        "################",
        "##===######===##"
      ]
    ]
  }]