[
  {
    "type": "part",
    "name": "building2_4",
    "xsize": 16,
    "zsize": 16,
    "slices": [
      [
        "#$$#$$#$$#$$#$$#",
        "$##############$",
        "$###1##########$",
        "################",
        "$#####1########$",
        "$##############$",
        "################",
        "$##############$",
        "$##############$",
        "#######l########",
        "$##############$",
        "$##############$",
        "################",
        "$##############$",
        "$##############$",
        "#$$#$$#$$#$$#$$#"
      ],
      [
        "################",
        "#        #     #",
        "#   F    #   # #",
        "#        #   # #",
        "#  F     #     #",
        "#        #     #",
        "##########     #",
        "#              #",
        "#              #",
        "#      l       #",
        "#     ###      #",
        "#              #",
        "#       F      #",
        "#              #",
        "#F             #",
        "################"
      ],
      [
        "#aa#aa#aa#aa#aa#",
        "a        :     a",
        "a        :   * a",
        "#        :   * #",
        "a        :     a",
        "a        :     a",
        "#::::::::#     #",
        "a              a",
        "a              a",
        "#      l       #",
        "a     ###      a",
        "a      T       a",
        "#              #",
        "a              a",
        "a              a",
        "#aa#aa#aa#aa#aa#"
      ],
      [
        "#aa#aa#aa#aa#aa#",
        "a        :     a",
        "a        :     a",
        "#        :     #",
        "a        :     a",
        "a        :     a",
        "#::::::::#     #",
        "a              a",
        "a              a",
        "#      l       #",
        "a     ###      a",
        "a              a",
        "#              #",
        "a              a",
        "a              a",
        "#aa#aa#aa#aa#aa#"
      ],
      [
        "################",
        "################",
        "################",
        "################",
        "################",
        "################",
        "################",
        "################",
        "################",
        "#######l########",
        "################",
        "################",
        "################",
        "################",
        "################",
        "################"
      ],
      [
        "################",
        "################",
        "################",
        "################",
        "################",
        "################",
        "################",
        "################",
        "################",
        "#######l########",
        "################",
        "################",
        "################",
        "################",
        "################",
        "################"
      ]
    ]
  }
]
