[
	{
		"type": "part",
		"name": "building1_1",
		"xsize": 16,
		"zsize": 16,
		"slices": [
			[
				"################",
				"################",
				"################",
				"################",
				"################",
				"################",
				"################",
				"################",
				"################",
				"#######l########",
				"##########1#####",
				"################",
				"################",
				"################",
				"################",
				"################"
			],
			[
				"#aa@aaaaaaaa@aa#",
				"a  #        #  a",
				"a  #F       #  a",
				"@  #F      L#  @",
				"a  #D      L#  a",
				"a  #        #  a",
				"a              a",
				"a  #        #  a",
				"a  #        #  a",
				"a  #   l    #  a",
				"a  ##########  a",
				"a              a",
				"@              @",
				"a              a",
				"a     F        a",
				"#aa@aaaaaaaa@aa#"
			],
			[
				"#aa@aaaaaaaa@aa#",
				"a  #        #  a",
				"a  #        #  a",
				"@  #       L#  @",
				"a  #*      L#  a",
				"a  #        #  a",
				"a              a",
				"a  #        #  a",
				"a  #        #  a",
				"a  #   l    #  a",
				"a  ##########  a",
				"a       T      a",
				"@              @",
				"a              a",
				"a              a",
				"#aa@aaaaaaaa@aa#"
			],
			[
				"#aa@aaaaaaaa@aa#",
				"a  #        #  a",
				"a  #        #  a",
				"@  #        #  @",
				"a  #        #  a",
				"a  #        #  a",
				"a  #        #  a",
				"a  #        #  a",
				"a  #        #  a",
				"a  #   l    #  a",
				"a  ##########  a",
				"a              a",
				"@              @",
				"a              a",
				"a              a",
				"#aa@aaaaaaaa@aa#"
			],
			[
				"################",
				"################",
				"################",
				"################",
				"################",
				"################",
				"################",
				"################",
				"################",
				"#######l########",
				"################",
				"################",
				"################",
				"################",
				"################",
				"################"
			],
			[
				"################",
				"################",
				"################",
				"################",
				"################",
				"################",
				"################",
				"################",
				"################",
				"#######l########",
				"################",
				"################",
				"################",
				"################",
				"################",
				"################"
			]
		]
	}
]