[ {
    "type": "part",
    "name": "building1_2",
    "xsize": 16,
    "zsize": 16,
    "slices": [
      [
        "################",
        "################",
        "################",
        "################",
        "################",
        "################",
        "################",
        "################",
        "################",
        "#######l########",
        "####1###########",
        "################",
        "################",
        "################",
        "################",
        "################"
      ],
      [
        "#aa@aaaaaaaa@aa#",
        "a  F      $$Q  a",
        "a              a",
        "@              @",
        "a   F          a",
        "a        F    Fa",
        "a              a",
        "a              a",
        "a              a",
        "a      l       a",
        "a###########  #a",
        "a              a",
        "@              @",
        "a    F         a",
        "a              a",
        "#aa@aaaaaaaa@aa#"
      ],
      [
        "#aa@aaaaaaaa@aa#",
        "a         **   a",
        "a              a",
        "@              @",
        "a              a",
        "a              a",
        "a              a",
        "a              a",
        "a              a",
        "a    T l       a",
        "a#::########  #a",
        "a    T         a",
        "@              @",
        "a              a",
        "a              a",
        "#aa@aaaaaaaa@aa#"
      ],
      [
        "#aa@aaaaaaaa@aa#",
        "a              a",
        "a              a",
        "@              @",
        "a              a",
        "a              a",
        "a              a",
        "a              a",
        "a              a",
        "a      l       a",
        "a##############a",
        "a              a",
        "@              @",
        "a              a",
        "a              a",
        "#aa@aaaaaaaa@aa#"
      ],
      [
        "################",
        "################",
        "################",
        "################",
        "################",
        "################",
        "################",
        "################",
        "################",
        "#######l########",
        "################",
        "################",
        "################",
        "################",
        "################",
        "################"
      ],
      [
        "################",
        "################",
        "################",
        "################",
        "################",
        "################",
        "################",
        "################",
        "################",
        "#######l########",
        "################",
        "################",
        "################",
        "################",
        "################",
        "################"
      ]
    ]
  }]