[  {
    "type": "part",
    "name": "building5_1",
    "xsize": 16,
    "zsize": 16,
    "slices": [
      [
        "################",
        "################",
        "################",
        "################",
        "################",
        "################",
        "################",
        "################",
        "################",
        "#######l########",
        "################",
        "################",
        "################",
        "################",
        "################",
        "################"
      ],
      [
        "##___######___##",
        "######    ######",
        "_#D#        #D#_",
        "_#D#        #D#_",
        "_#D#        #D#_",
        "####        ####",
        "#              #",
        "#F            L#",
        "#F            L#",
        "#      l       #",
        "##    ###     ##",
        "_#            #_",
        "_#    . .     #_",
        "_#            #_",
        "######    ######",
        "##___######___##"
      ],
      [
        "##   ######   ##",
        "##aaa#    #aaa##",
        " aK          Ka ",
        " aK          Ka ",
        " aK          Ka ",
        "##            ##",
        "#              #",
        "#             L#",
        "#             L#",
        "#      l       #",
        "##    ###     ##",
        " a            a ",
        " a    - -     a ",
        " a            a ",
        "##aaa#    #aaa##",
        "##   ######   ##"
      ],
      [
        "##   ######   ##",
        "##aaa#    #aaa##",
        " a            a ",
        " a            a ",
        " a            a ",
        "##T          T##",
        "#              #",
        "#              #",
        "#              #",
        "#      l       #",
        "##T   ###    T##",
        " a            a ",
        " a            a ",
        " a            a ",
        "##aaa#    #aaa##",
        "##   ######   ##"
      ],
      [
        "##   ######   ##",
        "##aaa#    #aaa##",
        " a            a ",
        " a            a ",
        " a            a ",
        "##            ##",
        "#              #",
        "#              #",
        "#              #",
        "#      l       #",
        "##    ###     ##",
        " a            a ",
        " a            a ",
        " a            a ",
        "##aaa#    #aaa##",
        "##   ######   ##"
      ],
      [
        "##===######===##",
        "################",
        "=##############=",
        "=##############=",
        "=##############=",
        "################",
        "################",
        "################",
        "################",
        "#######l########",
        "################",
        "=##############=",
        "=##############=",
        "=##############=",
        "################",
        "##===######===##"
      ]
    ]
  }]