[
  {
    "type": "part",
    "name": "building2_1",
    "xsize": 16,
    "zsize": 16,
    "slices": [
      [
        "#$$#$$#$$#$$#$$#",
        "$##############$",
        "$##############$",
        "################",
        "$##############$",
        "$##############$",
        "################",
        "$##############$",
        "$##############$",
        "#######l########",
        "$##############$",
        "$##############$",
        "################",
        "$##############$",
        "$##############$",
        "#$$#$$#$$#$$#$$#"
      ],
      [
        "################",
        "#              #",
        "#              #",
        "#              #",
        "#              #",
        "#              #",
        "#              #",
        "#              #",
        "#              #",
        "#      l       #",
        "#     ###      #",
        "#              #",
        "#              #",
        "#              #",
        "#              #",
        "################"
      ],
      [
        "#aa#aa#aa#aa#aa#",
        "a              a",
        "a              a",
        "#              #",
        "a              a",
        "a              a",
        "#              #",
        "a              a",
        "a              a",
        "#      l       #",
        "a     ###      a",
        "a              a",
        "#              #",
        "a              a",
        "a              a",
        "#aa#aa#aa#aa#aa#"
      ],
      [
        "#aa#aa#aa#aa#aa#",
        "a              a",
        "a              a",
        "#              #",
        "a              a",
        "a              a",
        "#              #",
        "a              a",
        "a              a",
        "#      l       #",
        "a     ###      a",
        "a              a",
        "#              #",
        "a              a",
        "a              a",
        "#aa#aa#aa#aa#aa#"
      ],
      [
        "################",
        "################",
        "################",
        "################",
        "################",
        "################",
        "################",
        "################",
        "################",
        "#######l########",
        "################",
        "################",
        "################",
        "################",
        "################",
        "################"
      ],
      [
        "################",
        "################",
        "################",
        "################",
        "################",
        "################",
        "################",
        "################",
        "################",
        "#######l########",
        "################",
        "################",
        "################",
        "################",
        "################",
        "################"
      ]
    ]
  }
]