[  {
    "type": "part",
    "name": "building1_4",
    "xsize": 16,
    "zsize": 16,
    "slices": [
      [
        "################",
        "################",
        "################",
        "################",
        "################",
        "################",
        "################",
        "################",
        "################",
        "#######l########",
        "################",
        "################",
        "################",
        "################",
        "################",
        "################"
      ],
      [
        "#aa@aaaaaaaa@aa#",
        "a              a",
        "a      F       a",
        "@              @",
        "a   F       F  a",
        "a              a",
        "a    ## ##     a",
        "a    #   #     a",
        "a    #   #     a",
        "a    # l #     a",
        "a# ############a",
        "a     FFF      a",
        "@              @",
        "a              a",
        "a              a",
        "#aa@aaaaaaaa@aa#"
      ],
      [
        "#aa@aaaaaaaa@aa#",
        "a              a",
        "a              a",
        "@              @",
        "a              a",
        "a              a",
        "a    ## ##     a",
        "a    #  T#     a",
        "a    #   #     a",
        "a    # l #     a",
        "a# ########aaa#a",
        "a              a",
        "@              @",
        "a              a",
        "a              a",
        "#aa@aaaaaaaa@aa#"
      ],
      [
        "#aa@aaaaaaaa@aa#",
        "a              a",
        "a              a",
        "@              @",
        "a              a",
        "a              a",
        "a    #####     a",
        "a    #   #     a",
        "a    #   #     a",
        "a    # l #     a",
        "a##############a",
        "a              a",
        "@              @",
        "a              a",
        "a              a",
        "#aa@aaaaaaaa@aa#"
      ],
      [
        "################",
        "################",
        "###1############",
        "################",
        "############1###",
        "################",
        "################",
        "################",
        "################",
        "#######l########",
        "################",
        "################",
        "################",
        "################",
        "################",
        "################"
      ],
      [
        "################",
        "################",
        "################",
        "################",
        "################",
        "################",
        "################",
        "################",
        "################",
        "#######l########",
        "################",
        "################",
        "################",
        "################",
        "################",
        "################"
      ]
    ]
  }]