[  {
    "type": "part",
    "name": "building6_4",
    "xsize": 16,
    "zsize": 16,
    "slices": [
      [
        "################",
        "################",
        "################",
        "################",
        "################",
        "################",
        "################",
        "################",
        "################",
        "#######l########",
        "################",
        "################",
        "################",
        "################",
        "################",
        "################"
      ],
      [
        "##___######___##",
        "######    ######",
        "_#WWW#        #_",
        "_#WWW#        #_",
        "_#####        #_",
        "##            ##",
        "#              #",
        "#              #",
        "#              #",
        "#      l       #",
        "##    ###     ##",
        "_#            #_",
        "_#            #_",
        "_#            #_",
        "######    ######",
        "##___######___##"
      ],
      [
        "##   ######   ##",
        "##aaa#    #aaa##",
        " a            a ",
        " a            a ",
        " a            a ",
        "##            ##",
        "#              #",
        "#              #",
        "#              #",
        "#      l       #",
        "##    ###     ##",
        " a            a ",
        " a            a ",
        " a            a ",
        "##aaa#    #aaa##",
        "##   ######   ##"
      ],
      [
        "##   ######   ##",
        "##aaa#    #aaa##",
        " a            a ",
        " a            a ",
        " a            a ",
        "##T          T##",
        "#              #",
        "#              #",
        "#              #",
        "#      l       #",
        "##T   ###    T##",
        " a            a ",
        " a            a ",
        " a            a ",
        "##aaa#    #aaa##",
        "##   ######   ##"
      ],
      [
        "##   ######   ##",
        "##aaa#    #aaa##",
        " a            a ",
        " a            a ",
        " a            a ",
        "##            ##",
        "#              #",
        "#              #",
        "#              #",
        "#      l       #",
        "##    ###     ##",
        " a            a ",
        " a            a ",
        " a            a ",
        "##aaa#    #aaa##",
        "##   ######   ##"
      ],
      [
        "##$$$$$$$$$$$$##",
        "################",
        "$##############$",
        "$##############$",
        "$##############$",
        "$##############$",
        "$##############$",
        "$##############$",
        "$##############$",
        "$######l#######$",
        "$##############$",
        "$##############$",
        "$##############$",
        "$##############$",
        "################",
        "##$$$$$$$$$$$$##"
      ]
    ]
  }]