[
  {
    "type": "part",
    "name": "building4_1",
    "xsize": 16,
    "zsize": 16,
    "slices": [
      [
        "#SSSSSSSSSSSSSS#",
        "S##############S",
        "S##############S",
        "S##############S",
        "S##############S",
        "S##############S",
        "S#####1########S",
        "S##############S",
        "S##############S",
        "S##############S",
        "S#########  ###S",
        "S#########  ###S",
        "S#########  ###S",
        "S#########cc###S",
        "S##############S",
        "#SSSSSSSSSSSSSS#"
      ],
      [
        "#aa#aa#aa#aa#aa#",
        "a     #        a",
        "a     #        a",
        "#C        F    #",
        "a     #        a",
        "a     #        a",
        "#######  F     #",
        "a    S#        a",
        "a    S#   cc   a",
        "#    S#  :dd:  #",
        "a     #  :  :  a",
        "a        :  :  a",
        "#    F#  :  :  #",
        "a    F#        a",
        "a     #        a",
        "#aa#aa#aa#aa#aa#"
      ],
      [
        "#aa#aa#aa#aa#aa#",
        "a     #        a",
        "a     #        a",
        "#              #",
        "a     #        a",
        "a     #        a",
        "##:::##T       #",
        "a     #        a",
        "a    *#        a",
        "#    *#   cc   #",
        "a     #   dd   a",
        "a              a",
        "#     #        #",
        "a     #        a",
        "a     #        a",
        "#aa#aa#aa#aa#aa#"
      ],
      [
        "#aa#aa#aa#aa#aa#",
        "a     #        a",
        "a     #        a",
        "#     #        #",
        "a     #        a",
        "a     #        a",
        "#######        #",
        "a     #        a",
        "a     #        a",
        "#     #        #",
        "a     #   cc   a",
        "a     #   dd   a",
        "#     #        #",
        "a     #        a",
        "a     #        a",
        "#aa#aa#aa#aa#aa#"
      ],
      [
        "#SSSSSSSSSSSSSS#",
        "S##############S",
        "S##############S",
        "S##############S",
        "S##############S",
        "S##############S",
        "S##############S",
        "S##############S",
        "S#########  ###S",
        "S#########  ###S",
        "S#########  ###S",
        "S#########cc###S",
        "S##############S",
        "S##############S",
        "S##############S",
        "#SSSSSSSSSSSSSS#"
      ],
      [
        "################",
        "################",
        "################",
        "################",
        "################",
        "################",
        "################",
        "################",
        "################",
        "##########  ####",
        "##########  ####",
        "##########  ####",
        "##########cc####",
        "################",
        "################",
        "################"
      ]
    ]
  }
]