[  {
    "type": "part",
    "name": "building5_2",
    "xsize": 16,
    "zsize": 16,
    "slices": [
      [
        "################",
        "################",
        "################",
        "################",
        "################",
        "################",
        "################",
        "################",
        "################",
        "#######l########",
        "################",
        "################",
        "################",
        "################",
        "################",
        "################"
      ],
      [
        "##___######___##",
        "######    ######",
        "_#            #_",
        "_#            #_",
        "_#            #_",
        "##            ##",
        "#              #",
        "#              #",
        "#              #",
        "#      l       #",
        "########### ####",
        "_#   FFFF     #_",
        "_#            #_",
        "_#            #_",
        "######    ######",
        "##___######___##"
      ],
      [
        "##   ######   ##",
        "##aaa#    #aaa##",
        " a            a ",
        " a            a ",
        " a            a ",
        "##            ##",
        "#              #",
        "#              #",
        "#              #",
        "#      l       #",
        "########### ####",
        " a            a ",
        " a            a ",
        " a            a ",
        "##aaa#    #aaa##",
        "##   ######   ##"
      ],
      [
        "##   ######   ##",
        "##aaa#    #aaa##",
        " a            a ",
        " a            a ",
        " a            a ",
        "##T          T##",
        "#              #",
        "#              #",
        "#              #",
        "#      l       #",
        "################",
        " a     T      a ",
        " a            a ",
        " a            a ",
        "##aaa#    #aaa##",
        "##   ######   ##"
      ],
      [
        "##   ######   ##",
        "##aaa#    #aaa##",
        " a            a ",
        " a            a ",
        " a            a ",
        "##            ##",
        "#              #",
        "#              #",
        "#              #",
        "#      l       #",
        "################",
        " a            a ",
        " a            a ",
        " a            a ",
        "##aaa#    #aaa##",
        "##   ######   ##"
      ],
      [
        "##===######===##",
        "################",
        "=##############=",
        "=##############=",
        "=##############=",
        "################",
        "################",
        "################",
        "################",
        "#######l########",
        "################",
        "=##############=",
        "=##############=",
        "=##############=",
        "################",
        "##===######===##"
      ]
    ]
  }]