[
  {
    "type": "part",
    "name": "building4_3",
    "xsize": 16,
    "zsize": 16,
    "slices": [
      [
        "#SSSSSSSSSSSSSS#",
        "S##############S",
        "S##############S",
        "S##############S",
        "S##############S",
        "S##############S",
        "S##############S",
        "S##############S",
        "S##############S",
        "S##############S",
        "S#########  ###S",
        "S#########  ###S",
        "S#########  ###S",
        "S#########cc###S",
        "S##############S",
        "#SSSSSSSSSSSSSS#"
      ],
      [
        "#aa#aa#aa#aa#aa#",
        "a     #  F     a",
        "a     Q        a",
        "#F    Q        #",
        "a     Q        a",
        "a     Q   F    a",
        "#F    #        #",
        "a   F          a",
        "a         cc   a",
        "#F    #  :dd:  #",
        "a     Q  :  :  a",
        "a     Q  :  :  a",
        "#     Q  :  :  #",
        "a     Q        a",
        "a     #        a",
        "#aa#aa#aa#aa#aa#"
      ],
      [
        "#aa#aa#aa#aa#aa#",
        "a     #        a",
        "a     Q        a",
        "#     Q        #",
        "a     Q        a",
        "a     Q        a",
        "#     #        #",
        "a              a",
        "a              a",
        "#     #   cc   #",
        "a     Q   dd   a",
        "a     Q        a",
        "#     Q        #",
        "a     Q        a",
        "a     #        a",
        "#aa#aa#aa#aa#aa#"
      ],
      [
        "#aa#aa#aa#aa#aa#",
        "a     #        a",
        "a     Q        a",
        "#     Q        #",
        "a     Q        a",
        "a     Q        a",
        "#     #        #",
        "a     #        a",
        "a     #        a",
        "#     #        #",
        "a     Q   cc   a",
        "a     Q   dd   a",
        "#     Q        #",
        "a     Q        a",
        "a     #        a",
        "#aa#aa#aa#aa#aa#"
      ],
      [
        "#SSSSSSSSSSSSSS#",
        "S##############S",
        "S##############S",
        "S##############S",
        "S##############S",
        "S##############S",
        "S##############S",
        "S##############S",
        "S#########  ###S",
        "S#########  ###S",
        "S#########  ###S",
        "S#########cc###S",
        "S##############S",
        "S##############S",
        "S##############S",
        "#SSSSSSSSSSSSSS#"
      ],
      [
        "################",
        "################",
        "################",
        "################",
        "################",
        "################",
        "################",
        "################",
        "################",
        "##########  ####",
        "##########  ####",
        "##########  ####",
        "##########cc####",
        "################",
        "################",
        "################"
      ]
    ]
  }
]
