[  {
    "type": "part",
    "name": "building3_1",
    "xsize": 16,
    "zsize": 16,
    "slices": [
      [
        "##   ######   ##",
        "################",
        " ############## ",
        " ############## ",
        " ############## ",
        "################",
        "################",
        "################",
        "################",
        "#######l########",
        "################",
        " ############## ",
        " ############## ",
        " ############## ",
        "################",
        "##   ######   ##"
      ],
      [
        "##   ######   ##",
        "##aaa#    #aaa##",
        " a            a ",
        " a            a ",
        " a            a ",
        "##            ##",
        "#              #",
        "#              #",
        "#              #",
        "#      l       #",
        "##    ###     ##",
        " a            a ",
        " a            a ",
        " a            a ",
        "##aaa#    #aaa##",
        "##   ######   ##"
      ],
      [
        "##   ######   ##",
        "##aaa#    #aaa##",
        " a            a ",
        " a            a ",
        " a            a ",
        "##            ##",
        "#              #",
        "#              #",
        "#              #",
        "#      l       #",
        "##    ###     ##",
        " a     T      a ",
        " a            a ",
        " a            a ",
        "##aaa#    #aaa##",
        "##   ######   ##"
      ],
      [
        "##   ######   ##",
        "##aaa#    #aaa##",
        " a            a ",
        " a            a ",
        " a            a ",
        "##            ##",
        "#              #",
        "#              #",
        "#              #",
        "#      l       #",
        "##    ###     ##",
        " a            a ",
        " a            a ",
        " a            a ",
        "##aaa#    #aaa##",
        "##   ######   ##"
      ],
      [
        "##   ######   ##",
        "################",
        " ############## ",
        " ############## ",
        " ############## ",
        "################",
        "################",
        "################",
        "################",
        "#######l########",
        "################",
        " ############## ",
        " ############## ",
        " ############## ",
        "################",
        "##   ######   ##"
      ],
      [
        "##   ######   ##",
        "################",
        " ############## ",
        " ############## ",
        " ############## ",
        "################",
        "################",
        "################",
        "################",
        "#######l########",
        "################",
        " ############## ",
        " ############## ",
        " ############## ",
        "################",
        "##   ######   ##"
      ]
    ]
  }]