[ {
    "type": "part",
    "name": "building2_2",
    "xsize": 16,
    "zsize": 16,
    "slices": [
      [
        "#$$#$$#$$#$$#$$#",
        "$##############$",
        "$##############$",
        "################",
        "$##############$",
        "$##############$",
        "################",
        "$##############$",
        "$##############$",
        "#######l########",
        "$##############$",
        "$##############$",
        "################",
        "$##############$",
        "$##############$",
        "#$$#$$#$$#$$#$$#"
      ],
      [
        "################",
        "#        #     #",
        "#        #     #",
        "#       F#     #",
        "#        #     #",
        "#  F           #",
        "#        #     #",
        "#        #     #",
        "#        #     #",
        "####   l #     #",
        "# C#######  F  #",
        "#              #",
        "#              #",
        "#       1   1  #",
        "#  F           #",
        "################"
      ],
      [
        "#aa#aa#aa#aa#aa#",
        "a        #     a",
        "a        #     a",
        "#        #     #",
        "a        #     a",
        "a              a",
        "#       T#     #",
        "a        #     a",
        "a        #     a",
        "####   l #     #",
        "a  #######     a",
        "a              a",
        "#              #",
        "a              a",
        "a              a",
        "#aa#aa#aa#aa#aa#"
      ],
      [
        "#aa#aa#aa#aa#aa#",
        "a        #     a",
        "a        #     a",
        "#        #     #",
        "a        #     a",
        "a        #     a",
        "#        #     #",
        "a        #     a",
        "a        #     a",
        "####   l #     #",
        "a  #######     a",
        "a              a",
        "#              #",
        "a              a",
        "a              a",
        "#aa#aa#aa#aa#aa#"
      ],
      [
        "################",
        "################",
        "################",
        "################",
        "################",
        "################",
        "################",
        "################",
        "################",
        "#######l########",
        "################",
        "################",
        "################",
        "################",
        "################",
        "################"
      ],
      [
        "################",
        "################",
        "################",
        "################",
        "################",
        "################",
        "################",
        "################",
        "################",
        "#######l########",
        "################",
        "################",
        "################",
        "################",
        "################",
        "################"
      ]
    ]
  }]
