[
  {
    "type": "part",
    "name": "building4_4",
    "xsize": 16,
    "zsize": 16,
    "slices": [
      [
        "#SSSSSSSSSSSSSS#",
        "S##############S",
        "S##############S",
        "S##############S",
        "S##############S",
        "S##############S",
        "S##############S",
        "S##############S",
        "S##############S",
        "S##############S",
        "S#########  ###S",
        "S#########  ###S",
        "S#########  ###S",
        "S#########cc###S",
        "S##############S",
        "#SSSSSSSSSSSSSS#"
      ],
      [
        "#aa#aa#aa#aa#aa#",
        "a  F  :        a",
        "a     :        a",
        "#F T  #        #",
        "a     :        a",
        "a     :        a",
        "#::#  #        #",
        "a              a",
        "a         cc   a",
        "#     #  :dd:  #",
        "a     :  :  :  a",
        "a     :  :  :  a",
        "#     #  :  :  #",
        "a     :        a",
        "a     :        a",
        "#aa#aa#aa#aa#aa#"
      ],
      [
        "#aa#aa#aa#aa#aa#",
        "a     :        a",
        "a     :        a",
        "#     #        #",
        "a     :        a",
        "a     :        a",
        "#::#  #        #",
        "a              a",
        "a              a",
        "#     #   cc   #",
        "a     :   dd   a",
        "a     :        a",
        "#     #        #",
        "a     :        a",
        "a     :        a",
        "#aa#aa#aa#aa#aa#"
      ],
      [
        "#aa#aa#aa#aa#aa#",
        "a     :        a",
        "a     :        a",
        "#     #        #",
        "a     :        a",
        "a     :        a",
        "#::#  #        #",
        "a              a",
        "a              a",
        "#     #        #",
        "a     :   cc   a",
        "a     :   dd   a",
        "#     #        #",
        "a     :        a",
        "a     :        a",
        "#aa#aa#aa#aa#aa#"
      ],
      [
        "#SSSSSSSSSSSSSS#",
        "S##############S",
        "S##############S",
        "S##############S",
        "S##############S",
        "S##############S",
        "S##############S",
        "S##############S",
        "S#########  ###S",
        "S#########  ###S",
        "S#########  ###S",
        "S#########cc###S",
        "S##############S",
        "S##############S",
        "S##############S",
        "#SSSSSSSSSSSSSS#"
      ],
      [
        "################",
        "################",
        "################",
        "################",
        "################",
        "################",
        "################",
        "################",
        "################",
        "##########  ####",
        "##########  ####",
        "##########  ####",
        "##########cc####",
        "################",
        "################",
        "################"
      ]
    ]
  }
]
