[  {
    "type": "part",
    "name": "building5_4",
    "xsize": 16,
    "zsize": 16,
    "slices": [
      [
        "################",
        "################",
        "################",
        "################",
        "################",
        "################",
        "################",
        "################",
        "################",
        "#######l########",
        "################",
        "################",
        "################",
        "################",
        "################",
        "################"
      ],
      [
        "##___######___##",
        "######    ######",
        "_#            #_",
        "_#       F    #_",
        "_#            #_",
        "##    F       ##",
        "#              #",
        "#         F    #",
        "#              #",
        "#      l       #",
        "##    ###     ##",
        "_#            #_",
        "_#  F         #_",
        "_#            #_",
        "######    ######",
        "##___######___##"
      ],
      [
        "##   ######   ##",
        "##aaa#    #aaa##",
        " a            a ",
        " a            a ",
        " a            a ",
        "##            ##",
        "#              #",
        "#              #",
        "#              #",
        "#      l       #",
        "##    ###     ##",
        " a            a ",
        " a            a ",
        " a            a ",
        "##aaa#    #aaa##",
        "##   ######   ##"
      ],
      [
        "##   ######   ##",
        "##aaa#    #aaa##",
        " a            a ",
        " a            a ",
        " a            a ",
        "##T          T##",
        "#              #",
        "#              #",
        "#              #",
        "#      l       #",
        "##T   ###    T##",
        " a            a ",
        " a            a ",
        " a            a ",
        "##aaa#    #aaa##",
        "##   ######   ##"
      ],
      [
        "##   ######   ##",
        "##aaa#    #aaa##",
        " a            a ",
        " a            a ",
        " a            a ",
        "##            ##",
        "#              #",
        "#              #",
        "#              #",
        "#      l       #",
        "##    ###     ##",
        " a            a ",
        " a            a ",
        " a            a ",
        "##aaa#    #aaa##",
        "##   ######   ##"
      ],
      [
        "##===######===##",
        "################",
        "=##############=",
        "=##############=",
        "=##############=",
        "################",
        "################",
        "################",
        "################",
        "#######l########",
        "################",
        "=##############=",
        "=##############=",
        "=##############=",
        "################",
        "##===######===##"
      ]
    ]
  }]