[
	{
		"type": "part",
		"name": "building1_8",
		"xsize": 16,
		"zsize": 16,
		"slices": [
			[
				"################",
				"################",
				"################",
				"################",
				"################",
				"################",
				"################",
				"################",
				"################",
				"#######l########",
				"################",
				"################",
				"################",
				"################",
				"################",
				"################"
			],
			[
				"#aa@aaaaaaaa@aa#",
				"a              a",
				"a     F        a",
				"@              @",
				"a              a",
				"a              a",
				"a    $$$$Q:::::a",
				"a    Q   Q     a",
				"a    Q   Q     a",
				"a      l       a",
				"a    $$$$Q     a",
				"a              a",
				"@  F           @",
				"a          F   a",
				"a              a",
				"#aa@aaaaaaaa@aa#"
			],
			[
				"#aa@aaaaaaaa@aa#",
				"a              a",
				"a              a",
				"@              @",
				"a              a",
				"a              a",
				"a    $$$$Q:::::a",
				"a    Q   Q     a",
				"a    Q   Q     a",
				"a      l       a",
				"a    $$$$Q     a",
				"a              a",
				"@              @",
				"a              a",
				"a              a",
				"#aa@aaaaaaaa@aa#"
			],
			[
				"#aa@aaaaaaaa@aa#",
				"a              a",
				"a              a",
				"@              @",
				"a              a",
				"a              a",
				"a    $$$$Q:::::a",
				"a    Q   Q     a",
				"a    Q   Q     a",
				"a    Q l Q     a",
				"a    $$$$Q     a",
				"a              a",
				"@              @",
				"a              a",
				"a              a",
				"#aa@aaaaaaaa@aa#"
			],
			[
				"################",
				"################",
				"################",
				"################",
				"################",
				"################",
				"################",
				"################",
				"################",
				"#######l########",
				"################",
				"################",
				"################",
				"################",
				"################",
				"################"
			],
			[
				"################",
				"################",
				"################",
				"################",
				"################",
				"################",
				"################",
				"################",
				"################",
				"#######l########",
				"################",
				"################",
				"################",
				"################",
				"################",
				"################"
			]
		]
	}
]