[ {
    "type": "part",
    "name": "building1_5",
    "xsize": 16,
    "zsize": 16,
    "slices": [
      [
        "################",
        "################",
        "################",
        "################",
        "################",
        "################",
        "################",
        "################",
        "################",
        "####X1XlX1X#####",
        "################",
        "################",
        "################",
        "################",
        "################",
        "################"
      ],
      [
        "#aa@aaaaaaaa@aa#",
        "a   LL         a",
        "a              a",
        "@         F    @",
        "a              a",
        "a              a",
        "a    ## ##     a",
        "a    #   #     a",
        "a    #   #     a",
        "a    X l X     a",
        "a  $$#####$$   a",
        "a      CF      a",
        "@  F           @",
        "a      F       a",
        "a              a",
        "#aa@aaaaaaaa@aa#"
      ],
      [
        "#aa@aaaaaaaa@aa#",
        "a   LL         a",
        "a              a",
        "@              @",
        "a              a",
        "a              a",
        "a    ## ##     a",
        "a    #  T#     a",
        "a    #   #     a",
        "a    # l #     a",
        "a  $$#####$$   a",
        "a              a",
        "@              @",
        "a              a",
        "a              a",
        "#aa@aaaaaaaa@aa#"
      ],
      [
        "#aa@aaaaaaaa@aa#",
        "a              a",
        "a              a",
        "@              @",
        "a              a",
        "a              a",
        "a    #####     a",
        "a    #   #     a",
        "a    #   #     a",
        "a    # l #     a",
        "a  $$#####$$   a",
        "a              a",
        "@              @",
        "a              a",
        "a              a",
        "#aa@aaaaaaaa@aa#"
      ],
      [
        "################",
        "################",
        "################",
        "################",
        "################",
        "################",
        "################",
        "################",
        "################",
        "#######l########",
        "################",
        "################",
        "################",
        "################",
        "################",
        "################"
      ],
      [
        "################",
        "################",
        "################",
        "################",
        "################",
        "################",
        "################",
        "################",
        "################",
        "#######l########",
        "################",
        "################",
        "################",
        "################",
        "################",
        "################"
      ]
    ]
  }]