[
	{
		"type": "part",
		"name": "center10_2",
		"xsize": 16,
		"zsize": 16,
		"slices": [
			[
				"##   #aaaa#   ##",
				"######$S$S######",
				"S$S$S$S$S$S$S$# ",
				"$S$S$S$S$S$S$S# ",
				"S$S$S$S$S$S$S$# ",
				"$S$S$S$S$S$S$S##",
				"S$S$S$S$S$S$S$Sa",
				"$S$S$S$S$S$S$S$a",
				"S$S$S$S$S$S$S$Sa",
				"$S$S$S$S$S$S$S$a",
				"S$S$S$S$S$S$S$##",
				"$S$S$S$S$S$S$S# ",
				"S$S$S$S$S$S$S$# ",
				"$S$S$S$S$S$S$S# ",
				"S$S$S$S$S$S$S$##",
				"$S$S$S$S$S$S$S##"
			],
			[
				"##   #aaaa#   ##",
				"##aaa#    #aaa##",
				"              a ",
				"              a ",
				"              a ",
				"   +++++++    ##",
				"   +$$$$Q+     a",
				"   +Q1$$Q+     a",
				"   +$$Q1Q+     a",
				"   +$$$$Q+     a",
				"   +++++++    ##",
				"              a ",
				"              a ",
				"              a ",
				"              ##",
				"              ##"
			],
			[
				"##   #aaaa#   ##",
				"##aaa#    #aaa##",
				"              a ",
				"              a ",
				"              a ",
				"   +++++++    ##",
				"   +$$$$Q+     a",
				"   +$$$$Q+     a",
				"   +$$$$Q+     a",
				"   +$$$$Q+     a",
				"   +++++++    ##",
				"              a ",
				"              a ",
				"              a ",
				"              ##",
				"              ##"
			],
			[
				"##   #aaaa#   ##",
				"##aaa#    #aaa##",
				"              a ",
				"              a ",
				"              a ",
				"   +++++++    ##",
				"   +$$$$Q+     a",
				"   +$$$$Q+     a",
				"   +$$$$Q+     a",
				"   +$$$$Q+     a",
				"   +++++++    ##",
				"              a ",
				"              a ",
				"              a ",
				"              ##",
				"              ##"
			],
			[
				"##   #aaaa#   ##",
				"##aaa#    #aaa##",
				"              a ",
				"              a ",
				"              a ",
				"   +++++++    ##",
				"   +$$$$Q+     a",
				"   +$$$$Q+     a",
				"   +$$$$Q+     a",
				"   +$$$$Q+     a",
				"   +++++++    ##",
				"              a ",
				"              a ",
				"              a ",
				"              ##",
				"              ##"
			],
			[
				"##   #aaaa#   ##",
				"################",
				"############### ",
				"############### ",
				"############### ",
				"################",
				"###############a",
				"###############a",
				"###############a",
				"###############a",
				"################",
				"############### ",
				"############### ",
				"############### ",
				"################",
				"################"
			]
		]
	}
]