[
  {
    "type": "part",
    "name": "center00_3",
    "xsize": 16,
    "zsize": 16,
    "slices": [
      [
        "##   #aaaa#   ##",
        "######$S$S######",
        " #S$S$S$S$S$S$S$",
        " #$S$S$S$S$S$S$S",
        " #S$S$S$S$S$S$S$",
        "##$S$S$S$S$S$S$S",
        "a$S$S$S$S$S$S$S$",
        "aS$S$S$S$S$S$S$S",
        "a$S$S$S$S$S$S$S$",
        "aS$S$S$S$S$S$S$S",
        "##S$S$S$S$S$S  $",
        " #$S$S$S$S$S$  S",
        " #S$S$S$S$S$S  $",
        " #$S$S$S$S$S$  S",
        "##S$S$S$S$S$S))$",
        "##$S$S$S$S$S$S$S"
      ],
      [
        "##   #aaaa#   ##",
        "##aaa#    #aaa##",
        " a              ",
        " a              ",
        " a              ",
        "##              ",
        "a               ",
        "a               ",
        "a               ",
        "a            )) ",
        "#########   Q  Q",
        " a FF ###   Q  Q",
        " a    ###   Q  Q",
        " a    ###   Q  Q",
        "### #####   Q  Q",
        "##              "
      ],
      [
        "##   #aaaa#   ##",
        "##aaa#    #aaa##",
        " a              ",
        " a              ",
        " a              ",
        "##              ",
        "a               ",
        "a               ",
        "a               ",
        "a    T          ",
        "#########   a))a",
        " a    ###   a  a",
        " a    ###   a  a",
        " a    ###   a  a",
        "### #####   a  a",
        "##              "
      ],
      [
        "##   #aaaa#   ##",
        "##aaa#    #aaa##",
        " a              ",
        " a              ",
        " a              ",
        "##              ",
        "a               ",
        "a               ",
        "a               ",
        "a               ",
        "#########   a  a",
        " a    ###   a))a",
        " a    ###   a  a",
        " a    ###   a  a",
        "### #####   a  a",
        "##              "
      ],
      [
        "##   #aaaa#   ##",
        "##aaa#    #aaa##",
        " a              ",
        " a              ",
        " a              ",
        "##              ",
        "a               ",
        "a               ",
        "a               ",
        "a               ",
        "#########   a  a",
        " a    ###   a  a",
        " a    ###   a))a",
        " a    ###   a  a",
        "### #####   a  a",
        "##              "
      ],
      [
        "##   #aaaa#   ##",
        "################",
        " ###############",
        " ###############",
        " ###############",
        "################",
        "a###############",
        "a###############",
        "a###############",
        "a###############",
        "#############  #",
        " ############  #",
        " ############  #",
        " ############))#",
        "#############  #",
        "################"
      ]
    ]
  }
]