[
  {
    "type": "part",
    "name": "center11_1",
    "xsize": 16,
    "zsize": 16,
    "slices": [
      [
        "S$S$S$S$S$S$S$##",
        "$          S$S##",
        "S          $S$# ",
        "$          S$S# ",
        "S          $S$# ",
        "$          S$S##",
        "S          $S$Sa",
        "$          S$S$a",
        "S          $S$Sa",
        "$          S$S$a",
        "S          $S$##",
        "$S$S$S$S$S$S$S# ",
        "S$S$S$S$S$S$S$# ",
        "$S$S$S$S$S$S$S# ",
        "######S$S$######",
        "##   #aaaa#   ##"
      ],
      [
        "::::::::::::  ##",
        ":          :  ##",
        ":          :  a ",
        ":          :  a ",
        ":          :  a ",
        ":          :  ##",
        ":          :   a",
        ":          :   a",
        ":          :   a",
        ":          :   a",
        ":          :  ##",
        "::::::::::::  a ",
        "              a ",
        "              a ",
        "##aaa#    #aaa##",
        "##   #aaaa#   ##"
      ],
      [
        "              ##",
        "              ##",
        "              a ",
        "              a ",
        "              a ",
        "              ##",
        "               a",
        "               a",
        "               a",
        "               a",
        "              ##",
        "              a ",
        "              a ",
        "              a ",
        "##aaa#    #aaa##",
        "##   #aaaa#   ##"
      ],
      [
        "              ##",
        "              ##",
        "              a ",
        "              a ",
        "              a ",
        "              ##",
        "               a",
        "               a",
        "               a",
        "               a",
        "              ##",
        "              a ",
        "              a ",
        "              a ",
        "##aaa#    #aaa##",
        "##   #aaaa#   ##"
      ],
      [
        "              ##",
        "              ##",
        "              a ",
        "              a ",
        "              a ",
        "              ##",
        "               a",
        "               a",
        "               a",
        "               a",
        "              ##",
        "              a ",
        "              a ",
        "              a ",
        "##aaa#    #aaa##",
        "##   #aaaa#   ##"
      ],
      [
        "################",
        "#          #####",
        "#          #### ",
        "#          #### ",
        "#          #### ",
        "#          #####",
        "#          ####a",
        "#          ####a",
        "#          ####a",
        "#          ####a",
        "#          #####",
        "############### ",
        "############### ",
        "############### ",
        "################",
        "##   #aaaa#   ##"
      ]
    ]
  }
]