[
	{
		"type": "part",
		"name": "center10_3",
		"xsize": 16,
		"zsize": 16,
		"slices": [
			[
				"##   #aaaa#   ##",
				"######$S$S######",
				"S$S$S$S$S$S$S$# ",
				"$S$S$S$S$S$S$S# ",
				"S$S$S$S$S$S$S$# ",
				"$S$S$S$S$S$S$S##",
				"S$S$S$S$S$S$S$Sa",
				"$S$S$S$S$S$S$S$a",
				"S$S$S$S$S$S$S$Sa",
				"$S$S$S$S$S$S$S$a",
				"S$S$S$S$S$S$S$##",
				"$S$S$S$S$S$S$S# ",
				"S$S$S$S$S$S$S$# ",
				"$S$S$S$S$S$S$S# ",
				"S$S$S$S$S$S$S$##",
				"$S$S$S$S$S$S$S##"
			],
			[
				"##   #aaaa#   ##",
				"##aaa#    #aaa##",
				"              a ",
				"              a ",
				"              a ",
				"  ###   ###   ##",
				"  +#+   +#+    a",
				"  :#:   :#:    a",
				"  +#+   +#+    a",
				"  :#:   :#:    a",
				"  +#+   +#+   ##",
				"  :#:   :#:   a ",
				"  +#+   +#+   a ",
				"  :#:   :#:   a ",
				"  +#+   +#+   ##",
				"  ###   ###   ##"
			],
			[
				"##   #aaaa#   ##",
				"##aaa#    #aaa##",
				"              a ",
				"              a ",
				"   T     T    a ",
				"  ###   ###   ##",
				"  +#+   +#+    a",
				"  :#:   :#:    a",
				"  +#+   +#+    a",
				"  :#:   :#:    a",
				"  +#+   +#+   ##",
				"  :#:   :#:   a ",
				"  +#+   +#+   a ",
				"  :#:   :#:   a ",
				"  +#+   +#+   ##",
				"  ###   ###   ##"
			],
			[
				"##   #aaaa#   ##",
				"##aaa#    #aaa##",
				"              a ",
				"              a ",
				"              a ",
				"  ###   ###   ##",
				"  +#+   +#+    a",
				"  :#:   :#:    a",
				"  +#+   +#+    a",
				"  :#:   :#:    a",
				"  +#+   +#+   ##",
				"  :#:   :#:   a ",
				"  +#+   +#+   a ",
				"  :#:   :#:   a ",
				"  +#+   +#+   ##",
				"  ###   ###   ##"
			],
			[
				"##   #aaaa#   ##",
				"##aaa#    #aaa##",
				"              a ",
				"              a ",
				"              a ",
				"  ###   ###   ##",
				"  +#+   +#+    a",
				"  :#:   :#:    a",
				"  +#+   +#+    a",
				"  :#:   :#:    a",
				"  +#+   +#+   ##",
				"  :#:   :#:   a ",
				"  +#+   +#+   a ",
				"  :#:   :#:   a ",
				"  +#+   +#+   ##",
				"  ###   ###   ##"
			],
			[
				"##   #aaaa#   ##",
				"################",
				"############### ",
				"############### ",
				"############### ",
				"################",
				"###############a",
				"###############a",
				"###############a",
				"###############a",
				"################",
				"############### ",
				"############### ",
				"############### ",
				"################",
				"################"
			]
		]
	}
]