[
  {
    "type": "part",
    "name": "center00_1",
    "xsize": 16,
    "zsize": 16,
    "slices": [
      [
        "##   #aaaa#   ##",
        "######$S$S######",
        " #S$S$S$S$S$S$S$",
        " #$S$S$S$S$S$S$S",
        " #S$S$S$S$S$S$S$",
        "##$S$S$S$S$S$S$S",
        "a$S$S$S$S$S$S$S$",
        "aS$S$S$S$S$S$S$S",
        "a$S$S$S$S$S$S$S$",
        "aS$S$S$S$S$S$S$S",
        "##S$S$S$S$S$S  $",
        " #$S$S$S$S$S$  S",
        " #S$S$S$S$S$S  $",
        " #$S$S$S$S$S$  S",
        "##S$S$S$S$S$S))$",
        "##$S$S$S$S$S$S$S"
      ],
      [
        "##   #aaaa#   ##",
        "##aaa#    #aaa##",
        " a              ",
        " a              ",
        " a              ",
        "##              ",
        "a               ",
        "a               ",
        "a               ",
        "a            )) ",
        "##          Q  Q",
        " a          Q  Q",
        " a          Q  Q",
        " a          Q  Q",
        "##          Q  Q",
        "##              "
      ],
      [
        "##   #aaaa#   ##",
        "##aaa#    #aaa##",
        " a              ",
        " a              ",
        " a              ",
        "##              ",
        "a               ",
        "a               ",
        "a               ",
        "a               ",
        "##          a))a",
        " a          a  a",
        " a          a  a",
        " a          a  a",
        "##          a  a",
        "##              "
      ],
      [
        "##   #aaaa#   ##",
        "##aaa#    #aaa##",
        " a              ",
        " a              ",
        " a              ",
        "##              ",
        "a               ",
        "a               ",
        "a               ",
        "a               ",
        "##          a  a",
        " a          a))a",
        " a          a  a",
        " a          a  a",
        "##          a  a",
        "##              "
      ],
      [
        "##   #aaaa#   ##",
        "##aaa#    #aaa##",
        " a              ",
        " a              ",
        " a              ",
        "##              ",
        "a               ",
        "a               ",
        "a               ",
        "a               ",
        "##          a  a",
        " a          a  a",
        " a          a))a",
        " a          a  a",
        "##          a  a",
        "##              "
      ],
      [
        "##   #aaaa#   ##",
        "################",
        " ###############",
        " ###############",
        " ###############",
        "################",
        "a###############",
        "a###############",
        "a###############",
        "a###############",
        "#############  #",
        " ############  #",
        " ############  #",
        " ############))#",
        "#############  #",
        "################"
      ]
    ]
  }
]