[  {
    "type": "part",
    "name": "center01_2",
    "xsize": 16,
    "zsize": 16,
    "slices": [
      [
        "##S$S$S$S$S$S$S$",
        "##$S$S$S$S$S$S$S",
        " #S$S$S$S$S$S$S$",
        " #$S$S$S$S$S$S$S",
        " #S$S$S$S$S$S$S$",
        "##$S$S$S$S$S$S$S",
        "a$S$S$S$S$S$S$S$",
        "aS$S$S$S$S$S$S$S",
        "a$S$S$S$S$S$S$S$",
        "aS$S$S$S$S$S$S$S",
        "##S$S$S$S$S$S$S$",
        " #$S$S$S$S$S$S$S",
        " #S$S$S$S$S$S$S$",
        " #$S$S$S$S$S$S$S",
        "######S$S$######",
        "##   #aaaa#   ##"
      ],
      [
        "##              ",
        "##    #+:+:+:+# ",
        " a    ######### ",
        " a    #+:+:+:+# ",
        " a              ",
        "##    #+:+:+:+# ",
        "a     ######### ",
        "a     #+:+:+:+# ",
        "a               ",
        "a     #+:+:+:+# ",
        "##    ######### ",
        " a    #+:+:+:+# ",
        " a              ",
        " a              ",
        "##aaa#    #aaa##",
        "##   #aaaa#   ##"
      ],
      [
        "##              ",
        "##    #+:+:+:+# ",
        " a   T######### ",
        " a    #+:+:+:+# ",
        " a              ",
        "##    #+:+:+:+# ",
        "a    T######### ",
        "a     #+:+:+:+# ",
        "a               ",
        "a     #+:+:+:+# ",
        "##   T######### ",
        " a    #+:+:+:+# ",
        " a              ",
        " a              ",
        "##aaa#    #aaa##",
        "##   #aaaa#   ##"
      ],
      [
        "##              ",
        "##    #+:+:+:+# ",
        " a    ######### ",
        " a    #+:+:+:+# ",
        " a              ",
        "##    #+:+:+:+# ",
        "a     ######### ",
        "a     #+:+:+:+# ",
        "a               ",
        "a     #+:+:+:+# ",
        "##    ######### ",
        " a    #+:+:+:+# ",
        " a              ",
        " a              ",
        "##aaa#    #aaa##",
        "##   #aaaa#   ##"
      ],
      [
        "##              ",
        "##    #+:+:+:+# ",
        " a    ######### ",
        " a    #+:+:+:+# ",
        " a              ",
        "##    #+:+:+:+# ",
        "a     ######### ",
        "a     #+:+:+:+# ",
        "a               ",
        "a     #+:+:+:+# ",
        "##    ######### ",
        " a    #+:+:+:+# ",
        " a              ",
        " a              ",
        "##aaa#    #aaa##",
        "##   #aaaa#   ##"
      ],
      [
        "################",
        "################",
        " ###############",
        " ###############",
        " ###############",
        "################",
        "a###############",
        "a###############",
        "a###############",
        "a###############",
        "################",
        " ###############",
        " ###############",
        " ###############",
        "################",
        "##   #aaaa#   ##"
      ]
    ]
  }]