[  {
    "type": "part",
    "name": "fountain4",
    "xsize": 16,
    "zsize": 16,
    "slices": [
      [
        "                ",
        "   ##########   ",
        "   #WWWWWWWW#   ",
        " ###WWWWWWWW### ",
        " #WW#WWWWWW#WW# ",
        " #WWW##__##WWW# ",
        " #WWW#    #WWW# ",
        " #WWW_ ## _WWW# ",
        " #WWW_ ## _WWW# ",
        " #WWW#    #WWW# ",
        " #WWW##__##WWW# ",
        " #WW#WWWWWW#WW# ",
        " ###WWWWWWWW### ",
        "   #WWWWWWWW#   ",
        "   ##########   ",
        "                "
      ],
      [
        "                ",
        "                ",
        "                ",
        "                ",
        "                ",
        "     wX  Xw     ",
        "     X    X     ",
        "       ##       ",
        "       ##       ",
        "     X    X     ",
        "     wX  Xw     ",
        "                ",
        "                ",
        "                ",
        "                ",
        "                "
      ],
      [
        "                ",
        "                ",
        "                ",
        "                ",
        "                ",
        "     wX  Xw     ",
        "     X    X     ",
        "       ##       ",
        "       ##       ",
        "     X    X     ",
        "     wX  Xw     ",
        "                ",
        "                ",
        "                ",
        "                ",
        "                "
      ],
      [
        "                ",
        "                ",
        "                ",
        "                ",
        "                ",
        "     wwXXww     ",
        "     w    w     ",
        "     X ## X     ",
        "     X ## X     ",
        "     w    w     ",
        "     wwXXww     ",
        "                ",
        "                ",
        "                ",
        "                ",
        "                "
      ],
      [
        "                ",
        "                ",
        "                ",
        "                ",
        "                ",
        "                ",
        "                ",
        "       __       ",
        "       __       ",
        "                ",
        "                ",
        "                ",
        "                ",
        "                ",
        "                ",
        "                "
      ]
    ]
  }
]