[
	{
		"type": "part",
		"name": "library10_2",
		"xsize": 16,
		"zsize": 16,
		"slices": [
			[
				"################",
				"SSSSSSSSSSSSSSS#",
				"SSSSSSSSSSSSSSS#",
				"#############SS#",
				"$$$$$$$$$$$$#SS#",
				"$$$$$$$$$$$$#SS#",
				"$$$$$$$$$$$$#SS#",
				"$$$$$$$$$$$$#SS#",
				"$$$$$$$$$$$$#SS#",
				"$$$$$$$$$$$$#SS#",
				"$$$$$$$$$$$$#SS#",
				"$$$$$$$$$$$$#SS#",
				"$$$$$$$$$$$$#SS#",
				"$$$$$$$$$$$$#SS#",
				"$$$$$$$$$$$$#SS#",
				"$$$$$$$$$$$$#SS#"
			],
			[
				"aaa#aaaa#aaaa#aa",
				"               a",
				"               #",
				"               a",
				"     LLLLL     a",
				"               a",
				"               a",
				"     .  .  .   #",
				"               a",
				"               a",
				"     .  .  .   a",
				"               a",
				"               #",
				"     LLLLL     a",
				"               a",
				"               a"
			],
			[
				"aaa#aaaa#aaaa#aa",
				"               a",
				"               #",
				"               a",
				"    TLLLLL     a",
				"               a",
				"               a",
				"     -  -  -   #",
				"               a",
				"               a",
				"     -  -  -   a",
				"               a",
				"               #",
				"    TLLLLL     a",
				"               a",
				"               a"
			],
			[
				"aaa#aaaa#aaaa#aa",
				"               a",
				"               #",
				"               a",
				"     LLLLL     a",
				"               a",
				"               a",
				"               #",
				"               a",
				"               a",
				"               a",
				"               a",
				"               #",
				"     LLLLL     a",
				"               a",
				"               a"
			],
			[
				"################",
				"               #",
				"               #",
				"               #",
				"               #",
				"               #",
				"               #",
				"               #",
				"               #",
				"               #",
				"               #",
				"               #",
				"               #",
				"               #",
				"               #",
				"               #"
			],
			[
				"################",
				"################",
				"################",
				"################",
				"################",
				"################",
				"################",
				"################",
				"################",
				"################",
				"################",
				"################",
				"################",
				"################",
				"################",
				"################"
			]
		]
	}
]