[
  {
    "type": "part",
    "name": "library10_1",
    "xsize": 16,
    "zsize": 16,
    "slices": [
      [
        "################",
        "SSSSSSSSSSSSSSS#",
        "SSSSSSSSSSSSSSS#",
        "#############SS#",
        "$$$$$$$$$$$$#SS#",
        "$$$$$$$$$$$$#SS#",
        "$$$$$$$$$$$$#SS#",
        "$$$$$$$$$$$$#SS#",
        "$$$$$$$$$$$$#SS#",
        "$$$$$$$$$$$$#SS#",
        "$$$$$$$$$$$$#SS#",
        "$$$$$$$$$$$$#SS#",
        "$$$$$$$$$$$$#SS#",
        "$$$$$$$$$$$$#SS#",
        "$$$$$$$$$$$$#SS#",
        "$$$$$$$$$$$$#SS#"
      ],
      [
        "aaa#aaaa#aaaa#aa",
        "               a",
        "               #",
        "               a",
        "     LLLL      a",
        "               a",
        "     LLLL      a",
        "               #",
        "     LLLL      a",
        "               a",
        "               a",
        "               a",
        "               #",
        "               a",
        "               a",
        "               a"
      ],
      [
        "aaa#aaaa#aaaa#aa",
        "               a",
        "               #",
        "               a",
        "    TLLLL      a",
        "               a",
        "     LLLL      a",
        "               #",
        "    TLLLL      a",
        "               a",
        "               a",
        "               a",
        "               #",
        "               a",
        "               a",
        "               a"
      ],
      [
        "aaa#aaaa#aaaa#aa",
        "               a",
        "               #",
        "               a",
        "     LLLL      a",
        "               a",
        "     LLLL      a",
        "               #",
        "     LLLL      a",
        "               a",
        "               a",
        "               a",
        "               #",
        "               a",
        "               a",
        "               a"
      ],
      [
        "################",
        "               #",
        "               #",
        "               #",
        "               #",
        "               #",
        "               #",
        "               #",
        "       %%      #",
        "               #",
        "               #",
        "               #",
        "               #",
        "               #",
        "               #",
        "               #"
      ],
      [
        "################",
        "################",
        "################",
        "################",
        "################",
        "################",
        "################",
        "################",
        "################",
        "################",
        "################",
        "################",
        "################",
        "################",
        "################",
        "################"
      ]
    ]
  }
]