[
  {
    "type": "part",
    "name": "library10_5",
    "xsize": 16,
    "zsize": 16,
    "slices": [
      [
        "################",
        "SSSSSSSSSSSSSSS#",
        "SSSSSSSSSSSSSSS#",
        "#############SS#",
        "$$$$$$$$$$$$#SS#",
        "$$$$$$$$$$$$#SS#",
        "$$$$$$$$$$$$#SS#",
        "$$$$$$$$$$$$#SS#",
        "$$$$$$$$$$$$#SS#",
        "$$$$$$$$$$$$#SS#",
        "$$$$$$$$$$$$#SS#",
        "$$$$$$$$$$$$#SS#",
        "$$$$$$$$$$$$#SS#",
        "$$$$$$$$$$$$#SS#",
        "$$$$$$$$$$$$#SS#",
        "$$$$$$$$$$$$#SS#"
      ],
      [
        "aaa#aaaa#aaaa#aa",
        "               a",
        "               #",
        "    FLLLLF     a",
        "  ##########   a",
        "  #1######1#   a",
        "  ##########   a",
        "  ###C C ###F  #",
        "  ###    ###L  a",
        "  ###  C ###L  a",
        "         ###L  a",
        "  ###   C###F  a",
        "  ##########   #",
        "  #4######1#   a",
        "  ##########   a",
        "    FLLLLF     a"
      ],
      [
        "aaa#aaaa#aaaa#aa",
        "               a",
        "               #",
        "   T LLLL      a",
        "  ##########   a",
        "  ##########   a",
        "  ##########   a",
        "  ###    ###   #",
        "  ###    ###L  a",
        "  ###    ###L  a",
        "         ###L  a",
        "  ###    ###   a",
        "  ##########   #",
        "  ##########   a",
        "  ##########   a",
        "     LLLL      a"
      ],
      [
        "aaa#aaaa#aaaa#aa",
        "               a",
        "               #",
        "     LLLL      a",
        "  ##########   a",
        "  ##########   a",
        "  ##########   a",
        "  ###    ###   #",
        "  ###    ###L  a",
        "  ###    ###L  a",
        "  ###    ###L  a",
        "  ###    ###   a",
        "  ##########   #",
        "  ##########   a",
        "  ##########   a",
        "     LLLL      a"
      ],
      [
        "################",
        "               #",
        "               #",
        "               #",
        "  ##########   #",
        "  ##########   #",
        "  ##########   #",
        "  ###%  %###   #",
        "  ###    ###   #",
        "  ###    ###   #",
        "  ###    ###   #",
        "  ###%  %###   #",
        "  ##########   #",
        "  ##########   #",
        "  ##########   #",
        "               #"
      ],
      [
        "################",
        "################",
        "################",
        "################",
        "################",
        "################",
        "################",
        "################",
        "################",
        "################",
        "################",
        "################",
        "################",
        "################",
        "################",
        "################"
      ]
    ]
  }
]