[
  {
    "type": "part",
    "name": "library01_2",
    "xsize": 16,
    "zsize": 16,
    "slices": [
      [
        "#SS#$$$$$$$$$$$$",
        "#SS#$$$$$$$$$$$$",
        "#SS#$$$$$$$$$$$$",
        "#SS#$$$$$$$$$$$$",
        "#SS#$$$$$$$$$$$$",
        "#SS#$$$$$$$$$$$$",
        "#SS#$$$$$$$$$$$$",
        "#SS#$$$$$$$$$$$$",
        "#SS#$$$$$$$$$$$$",
        "#SS#$$$$$$$$$$$$",
        "#SS#$$$$$$$$$$$$",
        "#SS#$$$$$$$$$$$$",
        "#SS#############",
        "#SSSSSSSSSSSSSSS",
        "#SSSSSSSSSSSSSSS",
        "################"
      ],
      [
        "a               ",
        "a               ",
        "a               ",
        "#               ",
        "a      LLLL     ",
        "a     $$$$$$    ",
        "a     QLLLLQ    ",
        "a     Q    Q    ",
        "#               ",
        "a     Q    Q    ",
        "a     QLLLLQ    ",
        "a     $$$$$$    ",
        "a      LLLL     ",
        "#               ",
        "a               ",
        "aa#aaaa#aaaa#aaa"
      ],
      [
        "a               ",
        "a               ",
        "a               ",
        "#               ",
        "a               ",
        "a      **       ",
        "a               ",
        "a               ",
        "#               ",
        "a               ",
        "a               ",
        "a        * *    ",
        "a               ",
        "#               ",
        "a               ",
        "aa#aaaa#aaaa#aaa"
      ],
      [
        "a               ",
        "a               ",
        "a               ",
        "#               ",
        "a               ",
        "a               ",
        "a               ",
        "a               ",
        "#               ",
        "a               ",
        "a               ",
        "a               ",
        "a               ",
        "#               ",
        "a               ",
        "aa#aaaa#aaaa#aaa"
      ],
      [
        "#               ",
        "#               ",
        "#               ",
        "#               ",
        "#               ",
        "#               ",
        "#               ",
        "#               ",
        "#               ",
        "#               ",
        "#               ",
        "#               ",
        "#               ",
        "#               ",
        "#               ",
        "################"
      ],
      [
        "################",
        "################",
        "################",
        "################",
        "################",
        "################",
        "################",
        "################",
        "################",
        "################",
        "################",
        "################",
        "################",
        "################",
        "################",
        "################"
      ]
    ]
  }
]