[
	{
		"type": "part",
		"name": "library10_4",
		"xsize": 16,
		"zsize": 16,
		"slices": [
			[
				"################",
				"SSSSSSSSSSSSSSS#",
				"SSSSSSSSSSSSSSS#",
				"#############SS#",
				"$$$$$$$$$$$$#SS#",
				"$$$$$$$$$$$$#SS#",
				"$$$$$$$$$$$$#SS#",
				"$$$$$$$$$$$$#SS#",
				"$$$$$$$$$$$$#SS#",
				"$$$$$$$$$$$$#SS#",
				"$$$$$$$$$$$$#SS#",
				"$$$$$$$$$$$$#SS#",
				"$$$$$$$$$$$$#SS#",
				"$$$$$$$$$$$$#SS#",
				"$$$$$$$$$$$$#SS#",
				"$$$$$$$$$$$$#SS#"
			],
			[
				"aaa#aaaa#aaaa#aa",
				"               a",
				"               #",
				"               a",
				"     LLLLLL    a",
				"               a",
				"     LLLLLL%   a",
				"               #",
				"     LLLLLLC   a",
				"               a",
				"    %LLLLLL    a",
				"               a",
				"     LLLLLL    #",
				"               a",
				"               a",
				"               a"
			],
			[
				"aaa#aaaa#aaaa#aa",
				"               a",
				"               #",
				"               a",
				"    TLLLLLL    a",
				"               a",
				"     LLLLLL    a",
				"               #",
				"     LLLLLL    a",
				"               a",
				"     LLLLLL    a",
				"               a",
				"    TLLLLLL    #",
				"               a",
				"               a",
				"               a"
			],
			[
				"aaa#aaaa#aaaa#aa",
				"               a",
				"               #",
				"               a",
				"     LLLLLL    a",
				"               a",
				"     LLLLLL    a",
				"               #",
				"     LLLLLL    a",
				"               a",
				"     LLLLLL    a",
				"               a",
				"               #",
				"               a",
				"               a",
				"               a"
			],
			[
				"################",
				"               #",
				"               #",
				"               #",
				"     %         #",
				"               #",
				"        %      #",
				"               #",
				"               #",
				"               #",
				"               #",
				"               #",
				"               #",
				"               #",
				"               #",
				"               #"
			],
			[
				"################",
				"################",
				"################",
				"################",
				"################",
				"################",
				"################",
				"################",
				"################",
				"################",
				"################",
				"################",
				"################",
				"################",
				"################",
				"################"
			]
		]
	}
]