[
  {
    "type": "part",
    "name": "library01_1",
    "xsize": 16,
    "zsize": 16,
    "slices": [
      [
        "#SS#$$$$$$$$$$$$",
        "#SS#$$$$$$$$$$$$",
        "#SS#$$$$$$$$$$$$",
        "#SS#$$$$$$$$$$$$",
        "#SS#$$$$$$$$$$$$",
        "#SS#$$$$$$$$$$$$",
        "#SS#$$$$$$$$$$$$",
        "#SS#$$$$$$$$$$$$",
        "#SS#$$$$$$$$$$$$",
        "#SS#$$$$$$$$$$$$",
        "#SS#$$$$$$$$$$$$",
        "#SS#$$$$$$$$$$$$",
        "#SS#############",
        "#SSSSSSSSSSSSSSS",
        "#SSSSSSSSSSSSSSS",
        "################"
      ],
      [
        "a               ",
        "a               ",
        "a               ",
        "#       %       ",
        "a      LLLL     ",
        "a               ",
        "a      LLLL     ",
        "a        %%     ",
        "#      LLLL     ",
        "a               ",
        "a      LLLL     ",
        "a      %%       ",
        "a               ",
        "#               ",
        "a               ",
        "aa#aaaa#aaaa#aaa"
      ],
      [
        "a               ",
        "a               ",
        "a               ",
        "#               ",
        "a      LLLLT    ",
        "a               ",
        "a      LLLL     ",
        "a               ",
        "#      LLLL     ",
        "a               ",
        "a      LLLLT    ",
        "a               ",
        "a               ",
        "#               ",
        "a               ",
        "aa#aaaa#aaaa#aaa"
      ],
      [
        "a               ",
        "a               ",
        "a               ",
        "#               ",
        "a      LLLL     ",
        "a               ",
        "a      LLLL     ",
        "a               ",
        "#      LLLL     ",
        "a               ",
        "a      LLLL     ",
        "a               ",
        "a               ",
        "#               ",
        "a               ",
        "aa#aaaa#aaaa#aaa"
      ],
      [
        "#               ",
        "#               ",
        "#               ",
        "#               ",
        "#               ",
        "#               ",
        "#               ",
        "#               ",
        "#               ",
        "#               ",
        "#               ",
        "#               ",
        "#               ",
        "#               ",
        "#               ",
        "################"
      ],
      [
        "################",
        "################",
        "################",
        "################",
        "################",
        "################",
        "################",
        "################",
        "################",
        "################",
        "################",
        "################",
        "################",
        "################",
        "################",
        "################"
      ]
    ]
  }
]