[  {
    "type": "part",
    "name": "library00_1",
    "xsize": 16,
    "zsize": 16,
    "slices": [
      [
        "################",
        "#SSSSSSSSSSSSSSS",
        "#SSSSSSSSSSSSSSS",
        "#SS#############",
        "#SS#$$$$$$$$$$$$",
        "#SS#$$$$$$$$$$$$",
        "#SS#$$$$$$$$$$$$",
        "#SS#$$$$$$$$$$$$",
        "#SS#$$$$$$$$$$$$",
        "#SS#$$$$$$$$$$$$",
        "#SS#$$$$$$$$$  $",
        "#SS#$$$$$$$$$  $",
        "#SS#$$$$$$$$$  $",
        "#SS#$$$$$$$$$  $",
        "#SS#$$$$$$$$$))$",
        "#SS#$$$$$$$$$$$$"
      ],
      [
        "aa#aaaa#aaaa#aaa",
        "a               ",
        "#               ",
        "a               ",
        "a      LLLL     ",
        "a               ",
        "a      LLLL     ",
        "#               ",
        "a               ",
        "a            )) ",
        "a           w  w",
        "a           w  w",
        "#           w  w",
        "a           w  w",
        "a           w  w",
        "a               "
      ],
      [
        "aa#aaaa#aaaa#aaa",
        "a               ",
        "#               ",
        "a               ",
        "a      LLLLT    ",
        "a               ",
        "a      LLLLT    ",
        "#               ",
        "a               ",
        "a               ",
        "a           :)):",
        "a           :  :",
        "#           :  :",
        "a           :  :",
        "a           :  :",
        "a               "
      ],
      [
        "aa#aaaa#aaaa#aaa",
        "a               ",
        "#               ",
        "a               ",
        "a      LLLL     ",
        "a               ",
        "a      LLLL     ",
        "#               ",
        "a               ",
        "a               ",
        "a           :  :",
        "a           :)):",
        "#           :  :",
        "a           :  :",
        "a           :  :",
        "a               "
      ],
      [
        "################",
        "#        %      ",
        "#               ",
        "#               ",
        "#               ",
        "#               ",
        "#               ",
        "#               ",
        "#               ",
        "#               ",
        "#          %:  :",
        "#           :  :",
        "#           :)):",
        "#          %:  :",
        "#           :  :",
        "#               "
      ],
      [
        "################",
        "################",
        "################",
        "################",
        "################",
        "################",
        "################",
        "################",
        "################",
        "################",
        "#############  #",
        "#############  #",
        "#############  #",
        "#############))#",
        "#############  #",
        "################"
      ]
    ]
  }]