[
  {
    "type": "part",
    "name": "library11_1",
    "xsize": 16,
    "zsize": 16,
    "slices": [
      [
        "$$$$$$$$$$$$#SS#",
        "$$$$$$$$$$$$#SS#",
        "$$$$$$$$$$$$#SS#",
        "$$$$$$$$$$$$#SS#",
        "$$$$$$$$$$$$#SS#",
        "$$$$$$$$$$$$#SS#",
        "$$$$$$$$$$$$#SS#",
        "$$$$$$$$$$$$#SS#",
        "$$$$$$$$$$$$#SS#",
        "$$$$$$$$$$$$#SS#",
        "$$$$$$$$$$$$#SS#",
        "$$$$$$$$$$$$#SS#",
        "#############SS#",
        "SSSSSSSSSSSSSSS#",
        "SSSSSSSSSSSSSSS#",
        "################"
      ],
      [
        "               a",
        "               a",
        "               a",
        "               #",
        "      LLLL     a",
        "               a",
        "      LLLL     a",
        "               a",
        "      LLLL     #",
        "               a",
        "      LLLL     a",
        "               a",
        "               a",
        "               #",
        "               a",
        "aaa#aaaa#aaaa#aa"
      ],
      [
        "               a",
        "               a",
        "               a",
        "               #",
        "     TLLLL     a",
        "               a",
        "     BLLLL     a",
        "               a",
        "      LLLL     #",
        "               a",
        "     TLLLL     a",
        "               a",
        "               a",
        "               #",
        "               a",
        "aaa#aaaa#aaaa#aa"
      ],
      [
        "               a",
        "               a",
        "               a",
        "               #",
        "      LLLL     a",
        "               a",
        "      LLLL     a",
        "               a",
        "      LLLL     #",
        "               a",
        "      LLLL     a",
        "               a",
        "               a",
        "               #",
        "               a",
        "aaa#aaaa#aaaa#aa"
      ],
      [
        "               #",
        "               #",
        "               #",
        "               #",
        "               #",
        "      %        #",
        "               #",
        "       %       #",
        "               #",
        "               #",
        "               #",
        "               #",
        "               #",
        "               #",
        "               #",
        "################"
      ],
      [
        "################",
        "################",
        "################",
        "################",
        "################",
        "################",
        "################",
        "################",
        "################",
        "################",
        "################",
        "################",
        "################",
        "################",
        "################",
        "################"
      ]
    ]
  }
]
