[  {
    "type": "part",
    "name": "park_building2",
    "xsize": 16,
    "zsize": 16,
    "slices": [
      [
        "                ",
        "      x  x      ",
        "                ",
        "   x        x   ",
        "                ",
        "                ",
        " x            x ",
        "                ",
        "                ",
        " x            x ",
        "                ",
        "                ",
        "   x        x   ",
        "                ",
        "      x  x      ",
        "                "
      ],
      [
        "                ",
        "      w  w      ",
        "      T  T      ",
        "   w        w   ",
        "                ",
        "                ",
        " wT          Tw ",
        "                ",
        "                ",
        " wT          Tw ",
        "                ",
        "                ",
        "   w        w   ",
        "      T  T      ",
        "      w  w      ",
        "                "
      ],
      [
        "                ",
        "      w  w      ",
        "                ",
        "   w        w   ",
        "                ",
        "                ",
        " w            w ",
        "                ",
        "                ",
        " w            w ",
        "                ",
        "                ",
        "   w        w   ",
        "                ",
        "      w  w      ",
        "                "
      ],
      [
        "                ",
        "      w  w      ",
        "                ",
        "   w        w   ",
        "                ",
        "                ",
        " w            w ",
        "                ",
        "                ",
        " w            w ",
        "                ",
        "                ",
        "   w        w   ",
        "                ",
        "      w  w      ",
        "                "
      ],
      [
        "                ",
        "      ____      ",
        "    ________    ",
        "   ___uuuu___   ",
        "  ___uuuuuu___  ",
        "  __uuuuuuuu__  ",
        " __uuuuuuuuuu__ ",
        " __uuuuuuuuuu__ ",
        " __uuuuuuuuuu__ ",
        " __uuuuuuuuuu__ ",
        "  __uuuuuuuu__  ",
        "  ___uuuuuu___  ",
        "   ___uuuu___   ",
        "    ________    ",
        "      ____      ",
        "                "
      ],
      [
        "                ",
        "                ",
        "                ",
        "                ",
        "                ",
        "       __       ",
        "      ____      ",
        "     ______     ",
        "     ______     ",
        "      ____      ",
        "       __       ",
        "                ",
        "                ",
        "                ",
        "                ",
        "                "
      ]
    ],
    "meta": []
  }]