[  {
    "type": "part",
    "name": "park_fountain2",
    "xsize": 16,
    "zsize": 16,
    "slices": [
      [
        "                ",
        " wwww      wwww ",
        " w     p p  p w ",
        " w   p        w ",
        " w           pw ",
        "           p    ",
        "  p    ###      ",
        "      #WWW# p   ",
        "    p #WWW#     ",
        "      #WWW#     ",
        "  p    ###p     ",
        " w    p     p w ",
        " w            w ",
        " w p     p    w ",
        " wwwwp     wwww ",
        "                "
      ],
      [
        "                ",
        " w  w      w  w ",
        "                ",
        "                ",
        " w            w ",
        "                ",
        "       wTw      ",
        "      w   w     ",
        "        W       ",
        "      w   w     ",
        "       wTw      ",
        " w            w ",
        "                ",
        "                ",
        " w  w      w  w ",
        "                "
      ],
      [
        "                ",
        " w  w      w  w ",
        "                ",
        "                ",
        " w            w ",
        "                ",
        "                ",
        "                ",
        "        W       ",
        "                ",
        "                ",
        "  w           w ",
        "                ",
        "                ",
        " w  w      w  w ",
        "                "
      ],
      [
        "                ",
        " ____      ____ ",
        " _            _ ",
        " _            _ ",
        " _            _ ",
        "                ",
        "                ",
        "                ",
        "                ",
        "                ",
        "                ",
        " _            _ ",
        " _            _ ",
        " _            _ ",
        " ____      ____ ",
        "                "
      ]
    ]
  }]