[  {
    "type": "part",
    "name": "park_building",
    "xsize": 16,
    "zsize": 16,
    "slices": [
      [
        "                ",
        "      x  x      ",
        "                ",
        "   x        x   ",
        "                ",
        "                ",
        " x            x ",
        "                ",
        "                ",
        " x            x ",
        "                ",
        "                ",
        "   x        x   ",
        "                ",
        "      x  x      ",
        "                "
      ],
      [
        "                ",
        "      w  w      ",
        "      T  T      ",
        "   w        w   ",
        "                ",
        "                ",
        " wT          Tw ",
        "                ",
        "                ",
        " wT          Tw ",
        "                ",
        "                ",
        "   w        w   ",
        "      T  T      ",
        "      w  w      ",
        "                "
      ],
      [
        "                ",
        "      w  w      ",
        "                ",
        "   w        w   ",
        "                ",
        "                ",
        " w            w ",
        "                ",
        "                ",
        " w            w ",
        "                ",
        "                ",
        "   w        w   ",
        "                ",
        "      w  w      ",
        "                "
      ],
      [
        "                ",
        "      w  w      ",
        "                ",
        "   w        w   ",
        "                ",
        "                ",
        " w            w ",
        "                ",
        "                ",
        " w            w ",
        "                ",
        "                ",
        "   w        w   ",
        "                ",
        "      w  w      ",
        "                "
      ],
      [
        "                ",
        "      ____      ",
        "    ________    ",
        "   __________   ",
        "  ____________  ",
        "  ____________  ",
        " ______________ ",
        " ______________ ",
        " ______________ ",
        " ______________ ",
        "  ____________  ",
        "  ____________  ",
        "   __________   ",
        "    ________    ",
        "      ____      ",
        "                "
      ]
    ]
  }]