 [ {
    "type": "part",
    "name": "shopping01_0",
    "xsize": 16,
    "zsize": 16,
    "slices": [
      [
        "#$$SS$$SS$$SS$$S",
        "#SS$$SS$$SS$$SSQ",
        "#SS$$SS$$SS$$SSQ",
        "#$$SS$$SS$$SS$$S",
        "#$$SS$$SS$$SS$$S",
        "#SS$$SS$$SS$$SSQ",
        "#SS$$SS$$SS$$SSQ",
        "#$$SS$$SS$$SS$$S",
        "#$$SS$$SS$$SS$$S",
        "#SS$$SS$$SS$$SSQ",
        "#SS$$SS$$SS$$SSQ",
        "#$$SS$$SS$$SS$$S",
        "#$$SS$$SS$$SS$$S",
        "#SS$$SS$$SS$$SSQ",
        "#SS$$SS$$SS$$SSQ",
        "################"
      ],
      [
        "a               ",
        "a               ",
        "a               ",
        "a               ",
        "a               ",
        "a               ",
        "a               ",
        "a               ",
        "a               ",
        "a               ",
        "a               ",
        "a               ",
        "a               ",
        "a               ",
        "a               ",
        "aaaaaaaaaaaaaaaa"
      ],
      [
        "a               ",
        "a               ",
        "a               ",
        "a               ",
        "a               ",
        "a               ",
        "a               ",
        "a               ",
        "a               ",
        "a               ",
        "a               ",
        "a               ",
        "a               ",
        "a               ",
        "a               ",
        "aaaaaaaaaaaaaaaa"
      ],
      [
        "a               ",
        "a               ",
        "a               ",
        "a               ",
        "a               ",
        "a               ",
        "a               ",
        "a               ",
        "a               ",
        "a               ",
        "a               ",
        "a               ",
        "a               ",
        "a               ",
        "a               ",
        "aaaaaaaaaaaaaaaa"
      ],
      [
        "a               ",
        "a               ",
        "a               ",
        "a               ",
        "a               ",
        "a               ",
        "a               ",
        "a               ",
        "a               ",
        "a               ",
        "a               ",
        "a               ",
        "a               ",
        "a               ",
        "a               ",
        "aaaaaaaaaaaaaaaa"
      ],
      [
        "a               ",
        "a               ",
        "a               ",
        "a               ",
        "a               ",
        "a               ",
        "a               ",
        "a               ",
        "a               ",
        "a               ",
        "a               ",
        "a               ",
        "a               ",
        "a               ",
        "a               ",
        "aaaaaaaaaaaaaaaa"
      ]
    ]
  }]