[  {
    "type": "part",
    "name": "shopping_open01_2",
    "xsize": 16,
    "zsize": 16,
    "meta": [
      {
        "key": "dontconnect",
        "boolean": true
      }
    ],
    "slices": [
      [
        " #######))))####",
        " #S$$SS$$SS$$SSQ",
        " #$SS$$SS$$SS$$S",
        " #$SS$$SS$$SS$$S",
        " #S$$SS$$SS$$SSQ",
        " #S$$SS$$SS$$SSQ",
        " #$SS$$SS$$SS$$S",
        " #$SS$$SS$$SS$$S",
        " #S$$SS$$SS$$SSQ",
        " #S$$SS$$SS$$SSQ",
        " #$SS$$SS$$SS$$S",
        " #$SS$$SS$$SS$$S",
        " #S$$SS$$SS$$SSQ",
        " #S$$SS$$SS$$SSQ",
        " ###############",
        "                "
      ],
      [
        " ::::::w    w:::",
        " :              ",
        " :              ",
        " :              ",
        " :              ",
        " :              ",
        " :              ",
        " :              ",
        " :              ",
        " :              ",
        " :              ",
        " :              ",
        " :              ",
        " :              ",
        " w::::::::::::::",
        "                "
      ],
      [
        "       T    T   ",
        "                ",
        "                ",
        "                ",
        "                ",
        "                ",
        "                ",
        "                ",
        "                ",
        "                ",
        "                ",
        "                ",
        "                ",
        "                ",
        " w              ",
        "                "
      ],
      [
        "                ",
        "                ",
        "                ",
        "                ",
        "                ",
        "                ",
        "                ",
        "                ",
        "                ",
        "                ",
        "                ",
        "                ",
        "                ",
        "                ",
        " w              ",
        "                "
      ],
      [
        "                ",
        "                ",
        "                ",
        "                ",
        "                ",
        "                ",
        "                ",
        "                ",
        "                ",
        "                ",
        "                ",
        "                ",
        "                ",
        "                ",
        " #              ",
        "                "
      ],
      [
        "################",
        "################",
        "################",
        "################",
        "################",
        "################",
        "################",
        "################",
        "################",
        "################",
        "################",
        "################",
        "################",
        "################",
        "################",
        "################"
      ]
    ]
  }]