[  {
    "type": "part",
    "name": "shopping10_0",
    "xsize": 16,
    "zsize": 16,
    "slices": [
      [
        "################",
        "$SS$$SS$$SS$$SS#",
        "$SS$$SS$$SS$$SS#",
        "S$$SS$$SS$$SS$$#",
        "S$$SS$$SS$$SS$$#",
        "$SS$$SS$$SS$$SS#",
        "$SS$$SS$$SS$$SS#",
        "S$$SS$$SS$$SS$$#",
        "S$$SS$$SS$$SS$$#",
        "$SS$$SS$$SS$$SS#",
        "$SS$$SS$$SS$$SS#",
        "S$$SS$$SS$$SS$$#",
        "S$$SS$$SS$$SS$$#",
        "$SS$$SS$$SS$$SS#",
        "$SS$$SS$$SS$$SS#",
        "S$$SS$$SS$$SS$$#"
      ],
      [
        "###   ####   ###",
        "# #####  #######",
        "              ##",
        "              # ",
        "              # ",
        "              # ",
        "              ##",
        "               #",
        "               #",
        "              ##",
        "              # ",
        "              # ",
        "              # ",
        "              ##",
        "               #",
        "               #"
      ],
      [
        "###   #aa#   ###",
        "# #aaa#  #aaa###",
        "              ##",
        "              a ",
        "              a ",
        "              a ",
        "              ##",
        "               a",
        "               a",
        "              ##",
        "              a ",
        "              a ",
        "              a ",
        "              ##",
        "               a",
        "               a"
      ],
      [
        "###   #aa#   ###",
        "# #aaa#  #aaa###",
        "      T  T    ##",
        "              a ",
        "              a ",
        "              a ",
        "             T##",
        "               a",
        "               a",
        "             T##",
        "              a ",
        "              a ",
        "              a ",
        "              ##",
        "               a",
        "               a"
      ],
      [
        "###   #aa#   ###",
        "# #aaa#  #aaa###",
        "              ##",
        "              a ",
        "              a ",
        "              a ",
        "              ##",
        "               a",
        "               a",
        "              ##",
        "              a ",
        "              a ",
        "              a ",
        "              ##",
        "               a",
        "               a"
      ],
      [
        "###   #aa#   ###",
        "# #aaa#  #aaa###",
        "              ##",
        "              a ",
        "              a ",
        "              a ",
        "              ##",
        "               a",
        "               a",
        "              ##",
        "              a ",
        "              a ",
        "              a ",
        "              ##",
        "               a",
        "               a"
      ]
    ]
  }]