[  {
    "type": "part",
    "name": "shopping_open00_0",
    "xsize": 16,
    "zsize": 16,
    "meta": [
      {
        "key": "dontconnect",
        "boolean": true
      }
    ],
    "slices": [
      [
        "################",
        "#SS$$SS$$SS$$SSQ",
        "#SS$$SS$$SS$$SSQ",
        "#$$SS$$SS$$SS$$S",
        "#$$SS$$SS$$SS$$S",
        "#SS$$SS$$SS$$SSQ",
        "#SS$$SS$$SS$$SSQ",
        "#$$SS$$SS$$SS$$S",
        "#$$SS$$SS$$SS$$S",
        "#SS$$SS$$SS$$SSQ",
        "#SS$$SS$$SS$$SSQ",
        "#$$SS$$SS$$SS$$S",
        "#$$SS$$SS$$SS$$S",
        "#SS$$SS$$SS$$SSQ",
        "#SS$$SS$$SS$$SSQ",
        "#$$SS$$SS$$SS$$S"
      ],
      [
        "                ",
        " #              ",
        "                ",
        "                ",
        "                ",
        "       #))))#   ",
        "                ",
        "                ",
        "                ",
        "       w    w   ",
        "                ",
        "                ",
        "                ",
        "                ",
        "                ",
        "       w    w   "
      ],
      [
        "                ",
        " w              ",
        "                ",
        "                ",
        "                ",
        "       w    w   ",
        "      T#))))#T  ",
        "                ",
        "                ",
        "       w    w   ",
        "                ",
        "                ",
        "                ",
        "                ",
        "                ",
        "       w    w   "
      ],
      [
        "                ",
        " w              ",
        "                ",
        "                ",
        "                ",
        "                ",
        "       w    w   ",
        "       #))))#   ",
        "                ",
        "       w    w   ",
        "                ",
        "                ",
        "                ",
        "                ",
        "                ",
        "       w    w   "
      ],
      [
        "                ",
        " w              ",
        "                ",
        "                ",
        "                ",
        "                ",
        "                ",
        "       w    w   ",
        "       #))))#   ",
        "       w    w   ",
        "                ",
        "                ",
        "                ",
        "                ",
        "                ",
        "       w    w   "
      ],
      [
        "                ",
        " w              ",
        "                ",
        "                ",
        "                ",
        "                ",
        "                ",
        "                ",
        "       w    w   ",
        "       #))))#   ",
        "                ",
        "                ",
        "                ",
        "                ",
        "                ",
        "       w    w   "
      ]
    ]
  }]