 [ {
    "type": "part",
    "name": "shopping11_r1",
    "xsize": 16,
    "zsize": 16,
    "slices": [
      [
        "S$$SS$$SS$$SS$$#",
        "$SS$$SS$$SS$$SS#",
        "$SS$$SS$$SS$$SS#",
        "S$$SS$$SS$$SS$$#",
        "S$$SS$$SS$$SS$$#",
        "$SS$$SS$$SS$$SS#",
        "$SS$$SS$$SS$$SS#",
        "S$$SS$$SS$$SS$$#",
        "S$$SS$$S  $SS$$#",
        "$SS$$SSQ  S$$SS#",
        "$SS$$SSQ  S$$SS#",
        "S$$SS$$S  $SS$$#",
        "S$$SS$$S  $SS$$#",
        "$SS$$SSQ))S$$SS#",
        "$SS$$SS$$SS$$SS#",
        "################"
      ],
      [
        "               #",
        "               #",
        "               #",
        "               #",
        "               #",
        "               #",
        "               #",
        "               #",
        "       `))`    #",
        "       `  `    #",
        "       `  `    #",
        "       `  `    #",
        "       `  `    #",
        "       `  `    #",
        "               #",
        "################"
      ],
      [
        "               #",
        "               #",
        "               #",
        "               #",
        "               #",
        "               #",
        "               #",
        "               #",
        "       `  `    #",
        "       `))`    #",
        "       `  `    #",
        "       `  `    #",
        "       `  `    #",
        "       `  `    #",
        "               #",
        "################"
      ],
      [
        "               a",
        "               #",
        "               a",
        "               a",
        "               #",
        "               a",
        "               a",
        "              T#",
        "       `  `    a",
        "       `  `    a",
        "       `))`    #",
        "       `  `    a",
        "       `  `    a",
        "       `  `    #",
        "               #",
        "a#aa#aa#aa#aa###"
      ],
      [
        "               #",
        "               #",
        "               #",
        "               #",
        "               #",
        "               #",
        "               #",
        "               #",
        "       `  `    #",
        "       `  `    #",
        "       `  `    #",
        "       `))`    #",
        "       `  `    #",
        "       `  `    #",
        "               #",
        "################"
      ],
      [
        "################",
        "################",
        "################",
        "################",
        "################",
        "################",
        "################",
        "################",
        "########  ######",
        "########  ######",
        "########  ######",
        "########  ######",
        "########))######",
        "################",
        "################",
        "################"
      ]
    ]
  }]