[  {
    "type": "part",
    "name": "shopping01_2",
    "xsize": 16,
    "zsize": 16,
    "meta": [
      {
        "key": "dontconnect",
        "boolean": true
      }
    ],
    "slices": [
      [
        "a   ####))))####",
        "a   #SS$$SS$$SSQ",
        "a   #$$SS$$SS$$S",
        "a   #$$SS$$SS$$S",
        "a   #SS$$SS$$SSQ",
        "a   #SS$$SS$$SSQ",
        "a   #$$SS$$SS$$S",
        "a   #$$SS$$SS$$S",
        "a   #SS$$SS$$SSQ",
        "a   #SS$$SS$$SSQ",
        "a   #$$SS$$SS$$S",
        "a   ############",
        "a               ",
        "a               ",
        "a               ",
        "aaaaaaaaaaaaaaaa"
      ],
      [
        "a   :::w    w:::",
        "a   :           ",
        "a   :           ",
        "a   :           ",
        "a   :           ",
        "a   :           ",
        "a   :           ",
        "a   :           ",
        "a   :           ",
        "a   :           ",
        "a   :           ",
        "a   ::::::::::::",
        "a               ",
        "a               ",
        "a               ",
        "aaaaaaaaaaaaaaaa"
      ],
      [
        "a      T    T   ",
        "a               ",
        "a               ",
        "a               ",
        "a               ",
        "a               ",
        "a               ",
        "a               ",
        "a               ",
        "a               ",
        "a               ",
        "a               ",
        "a               ",
        "a               ",
        "a               ",
        "aaaaaaaaaaaaaaaa"
      ],
      [
        "a               ",
        "a               ",
        "a               ",
        "a               ",
        "a               ",
        "a               ",
        "a               ",
        "a               ",
        "a               ",
        "a               ",
        "a               ",
        "a               ",
        "a               ",
        "a               ",
        "a               ",
        "aaaaaaaaaaaaaaaa"
      ],
      [
        "a               ",
        "a               ",
        "a               ",
        "a               ",
        "a               ",
        "a               ",
        "a               ",
        "a               ",
        "a               ",
        "a               ",
        "a               ",
        "a               ",
        "a               ",
        "a               ",
        "a               ",
        "aaaaaaaaaaaaaaaa"
      ],
      [
        "################",
        "################",
        "################",
        "################",
        "################",
        "################",
        "################",
        "################",
        "################",
        "################",
        "################",
        "################",
        "################",
        "################",
        "################",
        "################"
      ]
    ]
  }]