[  {
    "type": "part",
    "name": "shopping_open10_0",
    "xsize": 16,
    "zsize": 16,
    "slices": [
      [
        "################",
        "#SS$$SS$$SS$$SS#",
        "#SS$$SS$$SS$$SS#",
        "#$$SS$$SS$$SS$$#",
        "#$$SS$$SS$$SS$$#",
        "#SS$$SS$$SS$$SS#",
        "#SS$$SS$$SS$$SS#",
        "#$$SS$$SS$$SS$$#",
        "#$$SS$$SS$$SS$$#",
        "#SS$$SS$$SS$$SS#",
        "#SS$$SS$$SS$$SS#",
        "#$$SS$$SS$$SS$$#",
        "#$$SS$$SS$$SS$$#",
        "#SS$$SS$$SS$$SS#",
        "#SS$$SS$$SS$$SS#",
        "#$$SS$$SS$$SS$$#"
      ],
      [
        "###   ####   ###",
        "# #####  #######",
        "a             ##",
        "a             # ",
        "a             # ",
        "a             # ",
        "S             ##",
        "               #",
        "               #",
        "S             ##",
        "a             # ",
        "a             # ",
        "a             # ",
        "a             ##",
        "a              #",
        "a              #"
      ],
      [
        "###   #aa#   ###",
        "# #aaa#  #aaa###",
        "a     T  T    ##",
        "a             a ",
        "a             a ",
        "a             a ",
        "S            T##",
        "               a",
        "               a",
        "S            T##",
        "a             a ",
        "a             a ",
        "a             a ",
        "a             ##",
        "a              a",
        "a              a"
      ],
      [
        "###   #aa#   ###",
        "# #aaa#  #aaa###",
        "a             ##",
        "a             a ",
        "a             a ",
        "a             a ",
        "S             ##",
        "S              a",
        "S              a",
        "S             ##",
        "a             a ",
        "a             a ",
        "a             a ",
        "a             ##",
        "a              a",
        "a              a"
      ],
      [
        "###   #aa#   ###",
        "# #aaa#  #aaa###",
        "a             ##",
        "a             a ",
        "a             a ",
        "a             a ",
        "a             ##",
        "a              a",
        "a              a",
        "a             ##",
        "a             a ",
        "a             a ",
        "a             a ",
        "a             ##",
        "a              a",
        "a              a"
      ],
      [
        "###   #aa#   ###",
        "# #aaa#  #aaa###",
        "a             ##",
        "a             a ",
        "a             a ",
        "a             a ",
        "a             ##",
        "a              a",
        "a              a",
        "a             ##",
        "a             a ",
        "a             a ",
        "a             a ",
        "a             ##",
        "a              a",
        "a              a"
      ]
    ]
  }]