[  {
    "type": "part",
    "name": "shopping11_top",
    "xsize": 16,
    "zsize": 16,
    "slices": [
      [
        "                ",
        "                ",
        "                ",
        "                ",
        "                ",
        "                ",
        "                ",
        "                ",
        "                ",
        "                ",
        "                ",
        "                ",
        "                ",
        "                ",
        "                ",
        "                "
      ]
    ]
  },
  {
    "type": "part",
    "name": "shopping00_0",
    "xsize": 16,
    "zsize": 16,
    "slices": [
      [
        "################",
        "#SS##SS##SS##SS#",
        "#SS##SS##SS##SS#",
        "###SS##SS##SS##S",
        "###SS##SS##SS##S",
        "#SS##SS##SS##SS#",
        "#SS##SS##SS##SS#",
        "###SS##SS##SS##S",
        "###SS##SS##SS##S",
        "#SS##SS##SS##SS#",
        "#SS##SS##SS##SS#",
        "###SS##SS##SS##S",
        "###SS##SS##SS##S",
        "#SS##SS##SS##SS#",
        "#SS##SS##SS##SS#",
        "###SS##SS##SS##S"
      ],
      [
        "aaaaaaaaaaaaaaaa",
        "a               ",
        "a               ",
        "a               ",
        "a               ",
        "a      #))))#   ",
        "a               ",
        "a               ",
        "a               ",
        "a      w    w   ",
        "a               ",
        "a               ",
        "a               ",
        "a               ",
        "a               ",
        "a      w    w   "
      ],
      [
        "aaaaaaaaaaaaaaaa",
        "a               ",
        "a               ",
        "a               ",
        "a               ",
        "a      w    w   ",
        "a     T#))))#T  ",
        "a               ",
        "a               ",
        "a      w    w   ",
        "a               ",
        "a               ",
        "a               ",
        "a               ",
        "a               ",
        "a      w    w   "
      ],
      [
        "aaaaaaaaaaaaaaaa",
        "a               ",
        "a               ",
        "a               ",
        "a               ",
        "a               ",
        "a      w    w   ",
        "a      #))))#   ",
        "a               ",
        "a      w    w   ",
        "a               ",
        "a               ",
        "a               ",
        "a               ",
        "a               ",
        "a      w    w   "
      ],
      [
        "aaaaaaaaaaaaaaaa",
        "a               ",
        "a               ",
        "a               ",
        "a               ",
        "a               ",
        "a               ",
        "a      w    w   ",
        "a      #))))#   ",
        "a      w    w   ",
        "a               ",
        "a               ",
        "a               ",
        "a               ",
        "a               ",
        "a      w    w   "
      ],
      [
        "aaaaaaaaaaaaaaaa",
        "a               ",
        "a               ",
        "a               ",
        "a               ",
        "a               ",
        "a               ",
        "a               ",
        "a      w    w   ",
        "a      #))))#   ",
        "a               ",
        "a               ",
        "a               ",
        "a               ",
        "a               ",
        "a      w    w   "
      ]
    ]
  }]