[  {
    "type": "part",
    "name": "shopping11_1",
    "xsize": 16,
    "zsize": 16,
    "meta": [
      {
        "key": "dontconnect",
        "boolean": true
      }
    ],
    "slices": [
      [
        "               a",
        "               a",
        "              ##",
        "              a ",
        "              a ",
        "              a ",
        "              ##",
        "               a",
        "               a",
        "              ##",
        "              a ",
        "              a ",
        "              a ",
        "              ##",
        "  #aaa#  #aaa###",
        "###   #aa#   ###"
      ],
      [
        "               a",
        "               a",
        "              ##",
        "              a ",
        "              a ",
        "              a ",
        "              ##",
        "               a",
        "               a",
        "              ##",
        "              a ",
        "              a ",
        "              a ",
        "              ##",
        "  #aaa#  #aaa###",
        "###   #aa#   ###"
      ],
      [
        "               a",
        "               a",
        "              ##",
        "              a ",
        "              a ",
        "              a ",
        "              ##",
        "               a",
        "               a",
        "              ##",
        "              a ",
        "              a ",
        "              a ",
        "              ##",
        "  #aaa#  #aaa###",
        "###   #aa#   ###"
      ],
      [
        "               a",
        "               a",
        "              ##",
        "              a ",
        "              a ",
        "              a ",
        "              ##",
        "               a",
        "               a",
        "              ##",
        "              a ",
        "              a ",
        "              a ",
        "              ##",
        "  #aaa#  #aaa###",
        "###   #aa#   ###"
      ],
      [
        "               #",
        "               #",
        "              ##",
        "              # ",
        "              # ",
        "              # ",
        "              ##",
        "               #",
        "               #",
        "              ##",
        "              # ",
        "              # ",
        "              # ",
        "              ##",
        "  #####  #######",
        "###   ####   ###"
      ],
      [
        "              ##",
        "              ##",
        "              ##",
        "              ##",
        "              ##",
        "              ##",
        "              ##",
        "              ##",
        "              ##",
        "              ##",
        "              ##",
        "              ##",
        "              ##",
        "              ##",
        "################",
        "################"
      ]
    ]
  }]