[  {
    "type": "part",
    "name": "shopping10_r1",
    "xsize": 16,
    "zsize": 16,
    "slices": [
      [
        "################",
        "$SS$$SS$$SS$$SS#",
        "$SS$$SS$$SS$$SS#",
        "S$$SS$$SS$$SS$$#",
        "S$$SS$$SS$$SS$$#",
        "$SS$$SS$$SS$$SS#",
        "$SS$$SS$$SS$$SS#",
        "S$$SS$$SS$$SS$$#",
        "S$$SS$$SS$$SS$$#",
        "$SS$$SS$$SS$$SS#",
        "$SS$$SS$$SS$$SS#",
        "S$$SS$$SS$$SS$$#",
        "S$$SS$$SS$$SS$$#",
        "$SS$$SS$$SS$$SS#",
        "$SS$$SS$$SS$$SS#",
        "S$$SS$$SS$$SS$$#"
      ],
      [
        "################",
        "               #",
        "               #",
        "               #",
        "               #",
        "               #",
        "               #",
        "               #",
        "               #",
        "               #",
        "               #",
        "               #",
        "               #",
        "               #",
        "               #",
        "               #"
      ],
      [
        "################",
        "               #",
        "               #",
        "               #",
        "               #",
        "               #",
        "               #",
        "               #",
        "               #",
        "               #",
        "               #",
        "               #",
        "               #",
        "               #",
        "               #",
        "               #"
      ],
      [
        "a#aa#aa#aa#aa###",
        "       T       #",
        "               #",
        "               a",
        "               a",
        "               #",
        "               a",
        "               a",
        "              T#",
        "               a",
        "               a",
        "               #",
        "               a",
        "               a",
        "               #",
        "               a"
      ],
      [
        "################",
        "               #",
        "               #",
        "               #",
        "               #",
        "               #",
        "               #",
        "               #",
        "               #",
        "               #",
        "               #",
        "               #",
        "               #",
        "               #",
        "               #",
        "               #"
      ],
      [
        "################",
        "################",
        "################",
        "################",
        "################",
        "################",
        "################",
        "################",
        "################",
        "################",
        "################",
        "################",
        "################",
        "################",
        "################",
        "################"
      ]
    ]
  }]