[  {
    "type": "part",
    "name": "shopping00_1",
    "xsize": 16,
    "zsize": 16,
    "meta": [
      {
        "key": "dontconnect",
        "boolean": true
      }
    ],
    "slices": [
      [
        "aaaaaaaaaaaaaaaa",
        "a               ",
        "a               ",
        "a               ",
        "a               ",
        "a               ",
        "a               ",
        "a               ",
        "a               ",
        "a      w    w   ",
        "a      #))))#   ",
        "a               ",
        "a               ",
        "a               ",
        "a               ",
        "a      w    w   "
      ],
      [
        "aaaaaaaaaaaaaaaa",
        "a               ",
        "a               ",
        "a               ",
        "a               ",
        "a               ",
        "a               ",
        "a               ",
        "a               ",
        "a               ",
        "a      w    w   ",
        "a      #))))#   ",
        "a               ",
        "a               ",
        "a               ",
        "a      w    w   "
      ],
      [
        "aaaaaaaaaaaaaaaa",
        "a               ",
        "a               ",
        "a               ",
        "a               ",
        "a               ",
        "a               ",
        "a               ",
        "a               ",
        "a               ",
        "a               ",
        "a      w    w   ",
        "a      #))))#   ",
        "a               ",
        "a               ",
        "a      w    w   "
      ],
      [
        "aaaaaaaaaaaaaaaa",
        "a               ",
        "a               ",
        "a               ",
        "a               ",
        "a               ",
        "a               ",
        "a               ",
        "a               ",
        "a               ",
        "a               ",
        "a               ",
        "a      w    w   ",
        "a      #))))#   ",
        "a               ",
        "a      w    w   "
      ],
      [
        "aaaaaaaaaaaaaaaa",
        "a               ",
        "a               ",
        "a               ",
        "a               ",
        "a               ",
        "a               ",
        "a               ",
        "a               ",
        "a               ",
        "a               ",
        "a               ",
        "a               ",
        "a      w    w   ",
        "a      #))))#   ",
        "a      w    w   "
      ],
      [
        "aaaaaaaaaaaaaaaa",
        "a               ",
        "a               ",
        "a               ",
        "a               ",
        "a               ",
        "a               ",
        "a               ",
        "a               ",
        "a               ",
        "a               ",
        "a               ",
        "a               ",
        "a               ",
        "a      w    w   ",
        "a      #))))#   "
      ]
    ]
  }]