 [ {
    "type": "part",
    "name": "shopping10_2",
    "xsize": 16,
    "zsize": 16,
    "slices": [
      [
        "$$$$$$$$$$$$$$$$",
        "$SS$$SS$$SS$$SSQ",
        "$SS$$SS$$SS$$SSQ",
        "S$$SS$$SS$$SS$$Q",
        "S$$SS$$SS$$SS$$Q",
        "$SS$$SS$$SS$$SSQ",
        "$SS$$SS$$SS$$SSQ",
        "S$$SS$$SS$$SS$$Q",
        "S$$SS$$SS$$SS$$Q",
        "$SS$$SS$$SS$$SSQ",
        "$SS$$SS$$SS$$SSQ",
        "S$$SS$$SS$$SS$$Q",
        "S$$SS$$SS$$SS$$Q",
        "$SS$$SS$$SS$$SSQ",
        "$SS$$SS$$SS$$SSQ",
        "S$$SS$$SS$$SS$$Q"
      ],
      [
        "################",
        ":              #",
        ":              #",
        ":              #",
        ":              #",
        ":              #",
        ":              #",
        ":              #",
        ":              #",
        ":              #",
        ":              #",
        ":              #",
        ":              #",
        ":              #",
        ":              #",
        ":              #"
      ],
      [
        "################",
        "               #",
        "               #",
        "               #",
        "               #",
        "               #",
        "               #",
        "               #",
        "               #",
        "               #",
        "               #",
        "               #",
        "               #",
        "               #",
        "               #",
        "               #"
      ],
      [
        "##aa#aa#aa#aa###",
        "       T       #",
        "               #",
        "               a",
        "               a",
        "               #",
        "               a",
        "               a",
        "              T#",
        "               a",
        "               a",
        "               #",
        "               a",
        "               a",
        "               #",
        "               a"
      ],
      [
        "################",
        "               #",
        "               #",
        "               #",
        "               #",
        "               #",
        "               #",
        "               #",
        "               #",
        "               #",
        "               #",
        "               #",
        "               #",
        "               #",
        "               #",
        "               #"
      ],
      [
        "################",
        "################",
        "################",
        "################",
        "################",
        "################",
        "################",
        "################",
        "################",
        "################",
        "################",
        "################",
        "################",
        "################",
        "################",
        "################"
      ]
    ]
  }]