 [ {
    "type": "part",
    "name": "shopping01_r1",
    "xsize": 16,
    "zsize": 16,
    "slices": [
      [
        "#$$SS$$SS$$SS$$S",
        "#SS$$SS$$SS$$SSQ",
        "#SS$$SS$$SS$$SSQ",
        "#$$SS$$SS$$SS$$S",
        "#$$SS$$SS$$SS$$S",
        "#SS$$SS$$SS$$SSQ",
        "#SS$$SS$$SS$$SSQ",
        "#$$SS$$SS$$SS$$S",
        "#$$SS$$SS$$SS$$S",
        "#SS$$SS$$SS$$SSQ",
        "#SS$$SS$$SS$$SSQ",
        "#$$SS$$SS$$SS$$S",
        "#$$SS$$SS$$SS$$S",
        "#SS$$SS$$SS$$SSQ",
        "#SS$$SS$$SS$$SSQ",
        "################"
      ],
      [
        "#               ",
        "#               ",
        "#               ",
        "#               ",
        "#               ",
        "#               ",
        "#               ",
        "#               ",
        "#               ",
        "#               ",
        "#               ",
        "#               ",
        "#               ",
        "#               ",
        "#               ",
        "################"
      ],
      [
        "#               ",
        "#               ",
        "#               ",
        "#               ",
        "#               ",
        "#               ",
        "#               ",
        "#               ",
        "#               ",
        "#               ",
        "#               ",
        "#               ",
        "#               ",
        "#               ",
        "#               ",
        "################"
      ],
      [
        "a               ",
        "#               ",
        "a               ",
        "a               ",
        "#               ",
        "a               ",
        "a               ",
        "#T              ",
        "a               ",
        "a               ",
        "#               ",
        "a               ",
        "a               ",
        "#               ",
        "#       T       ",
        "###aa#aa#aa#aa#a"
      ],
      [
        "#               ",
        "#               ",
        "#               ",
        "#               ",
        "#               ",
        "#               ",
        "#               ",
        "#               ",
        "#               ",
        "#               ",
        "#               ",
        "#               ",
        "#               ",
        "#               ",
        "#               ",
        "################"
      ],
      [
        "################",
        "################",
        "################",
        "################",
        "################",
        "################",
        "################",
        "################",
        "################",
        "################",
        "################",
        "################",
        "################",
        "################",
        "################",
        "################"
      ]
    ]
  }]