[  {
    "type": "part",
    "name": "shopping00_r1",
    "xsize": 16,
    "zsize": 16,
    "slices": [
      [
        "################",
        "#SS$$SS$$SS$$SSQ",
        "#SS$$SS$$SS$$SSQ",
        "#$$SS$$SS$$SS$$S",
        "#$$SS$$SS$$SS$$S",
        "#SS$$SS$$SS$$SSQ",
        "#SS$$SS$$SS$$SSQ",
        "#$$SS$$SS$$SS$$S",
        "#$$SS$$SS$$SS$$S",
        "#SS$$SS$$SS$$SSQ",
        "#SS$$SS$$SS$$SSQ",
        "#$$SS$$SS$$SS$$S",
        "#$$SS$$SS$$SS$$S",
        "#SS$$SS$$SS$$SSQ",
        "#SS$$SS$$SS$$SSQ",
        "#$$SS$$SS$$SS$$S"
      ],
      [
        "################",
        "#               ",
        "#               ",
        "#               ",
        "#               ",
        "#               ",
        "#               ",
        "#               ",
        "#               ",
        "#               ",
        "#               ",
        "#               ",
        "#               ",
        "#               ",
        "#               ",
        "#               "
      ],
      [
        "################",
        "#               ",
        "#               ",
        "#               ",
        "#               ",
        "#               ",
        "#               ",
        "#               ",
        "#               ",
        "#               ",
        "#               ",
        "#               ",
        "#               ",
        "#               ",
        "#               ",
        "#               "
      ],
      [
        "###aa#aa#aa#aa#a",
        "#               ",
        "#               ",
        "a               ",
        "a               ",
        "#               ",
        "a               ",
        "a               ",
        "#               ",
        "a               ",
        "a               ",
        "#               ",
        "a               ",
        "a               ",
        "#               ",
        "a               "
      ],
      [
        "################",
        "#               ",
        "#               ",
        "#               ",
        "#               ",
        "#               ",
        "#               ",
        "#               ",
        "#               ",
        "#               ",
        "#               ",
        "#               ",
        "#               ",
        "#               ",
        "#               ",
        "#               "
      ],
      [
        "################",
        "################",
        "################",
        "################",
        "################",
        "################",
        "################",
        "################",
        "################",
        "################",
        "################",
        "################",
        "################",
        "################",
        "################",
        "################"
      ]
    ]
  }]