 [ {
    "type": "part",
    "name": "shopping11_0",
    "xsize": 16,
    "zsize": 16,
    "slices": [
      [
        "S$$SS$$SS$$SS$$#",
        "$SS$$SS$$SS$$SS#",
        "$SS$$SS$$SS$$SS#",
        "S$$SS$$SS$$SS$$#",
        "S$$SS$$SS$$SS$$#",
        "$SS$$SS$$SS$$SS#",
        "$SS$$SS$$SS$$SS#",
        "S$$SS$$SS$$SS$$#",
        "S$$SS$$SS$$SS$$#",
        "$SS$$SS$$SS$$SS#",
        "$SS$$SS$$SS$$SS#",
        "S$$SS$$SS$$SS$$#",
        "S$$SS$$SS$$SS$$#",
        "$SS$$SS$$SS$$SS#",
        "$SS$$SS$$SS$$SS#",
        "################"
      ],
      [
        "               #",
        "               #",
        "              ##",
        "              # ",
        "              # ",
        "              # ",
        "              ##",
        "               #",
        "               #",
        "              ##",
        "              # ",
        "              # ",
        "              # ",
        "              ##",
        "  #####  #######",
        "###   ####   ###"
      ],
      [
        "               a",
        "               a",
        "              ##",
        "              a ",
        "              a ",
        "              a ",
        "              ##",
        "               a",
        "               a",
        "              ##",
        "              a ",
        "              a ",
        "              a ",
        "              ##",
        "  #aaa#  #aaa###",
        "###   #aa#   ###"
      ],
      [
        "               a",
        "               a",
        "              ##",
        "              a ",
        "              a ",
        "              a ",
        "             T##",
        "               a",
        "               a",
        "             T##",
        "              a ",
        "              a ",
        "              a ",
        "      T  T    ##",
        "  #aaa#  #aaa###",
        "###   #aa#   ###"
      ],
      [
        "               a",
        "               a",
        "              ##",
        "              a ",
        "              a ",
        "              a ",
        "              ##",
        "               a",
        "               a",
        "              ##",
        "              a ",
        "              a ",
        "              a ",
        "              ##",
        "  #aaa#  #aaa###",
        "###   #aa#   ###"
      ],
      [
        "               a",
        "               a",
        "              ##",
        "              a ",
        "              a ",
        "              a ",
        "              ##",
        "               a",
        "               a",
        "              ##",
        "              a ",
        "              a ",
        "              a ",
        "              ##",
        "  #aaa#  #aaa###",
        "###   #aa#   ###"
      ]
    ]
  }]