[
  {
    "type": "part",
    "name": "shopping_open11_2",
    "xsize": 16,
    "zsize": 16,
    "slices": [
      [
        "S$$SS$$SS$$SS$$$",
        "$SS$$SS$$SS$$SS$",
        "$SS$$SS$$SS$$SS$",
        "S$$SS$$SS$$SS$$$",
        "S$$SS$$SS$$SS$$$",
        "$SS$$SS$$SS$$SS$",
        "$SS$$SS$$SS$$SS$",
        "S$$SS$$SS$$SS$$$",
        "S$$SS$$SS$$SS$$$",
        "$SS$$SS$$SS$$SS$",
        "$SS$$SS$$SS$$SS$",
        "S$$SS$$SS$$SS$$$",
        "S$$SS$$SS$$SS$$$",
        "$SS$$SS$$SS$$SS$",
        "$SS$$SS$$SS$$SS$",
        "$$$$$$$$$$$$$$$$"
      ],
      [
        "#              #",
        "               #",
        "               #",
        "               #",
        "               #",
        "               #",
        "               #",
        "               #",
        "       `))`    #",
        "       `  `    #",
        "       `  `    #",
        "#      `  `    #",
        "#      `  `    #",
        "#      `  `    #",
        "#              #",
        "################"
      ],
      [
        "#              #",
        "               #",
        "               #",
        "               #",
        "               #",
        "               #",
        "               #",
        "               #",
        "       `  `    #",
        "       `))`    #",
        "       `       #",
        "#      `       #",
        "#      `       #",
        "#      `       #",
        "#              #",
        "################"
      ],
      [
        "#              a",
        "               #",
        "               a",
        "               a",
        "               #",
        "               a",
        "               a",
        "              T#",
        "       `  `    a",
        "       `  `    a",
        "       `))`    #",
        "#      `  `    a",
        "#      `  `    a",
        "#      `  `    #",
        "#              #",
        "##aa#aa#aa#aa###"
      ],
      [
        "#              #",
        "               #",
        "               #",
        "               #",
        "               #",
        "               #",
        "               #",
        "               #",
        "       `  `    #",
        "       `  `    #",
        "       `  `    #",
        "#      `))`    #",
        "#      `  `    #",
        "#      `  `    #",
        "#              #",
        "################"
      ],
      [
        "################",
        "################",
        "################",
        "################",
        "################",
        "################",
        "################",
        "################",
        "########  ######",
        "########  ######",
        "########  ######",
        "########  ######",
        "########))######",
        "################",
        "################",
        "################"
      ]
    ]
  }
]