 [ {
    "type": "part",
    "name": "shopping_open11_0",
    "xsize": 16,
    "zsize": 16,
    "slices": [
      [
        "#$$SS$$SS$$SS$$#",
        "#SS$$SS$$SS$$SS#",
        "#SS$$SS$$SS$$SS#",
        "#$$SS$$SS$$SS$$#",
        "#$$SS$$SS$$SS$$#",
        "#SS$$SS$$SS$$SS#",
        "#SS$$SS$$SS$$SS#",
        "#$$SS$$SS$$SS$$#",
        "#$$SS$$SS$$SS$$#",
        "#SS$$SS$$SS$$SS#",
        "#SS$$SS$$SS$$SS#",
        "#$$SS$$SS$$SS$$#",
        "#$$SS$$SS$$SS$$#",
        "#SS$$SS$$SS$$SS#",
        "#SS$$SS$$SS$$SS#",
        "################"
      ],
      [
        "a              #",
        "a              #",
        "a             ##",
        "a             # ",
        "a             # ",
        "a             # ",
        "a             ##",
        "a              #",
        "a              #",
        "a             ##",
        "a             # ",
        "a             # ",
        "a             # ",
        "a             ##",
        "a #####  #######",
        "###   ####   ###"
      ],
      [
        "a              a",
        "a              a",
        "a             ##",
        "a             a ",
        "a             a ",
        "a             a ",
        "a            T##",
        "a              a",
        "a              a",
        "a            T##",
        "a             a ",
        "a             a ",
        "a             a ",
        "a     T  T    ##",
        "a #aaa#  #aaa###",
        "###   #aa#   ###"
      ],
      [
        "a              a",
        "a              a",
        "a             ##",
        "a             a ",
        "a             a ",
        "a             a ",
        "a             ##",
        "a              a",
        "a              a",
        "a             ##",
        "a             a ",
        "a             a ",
        "a             a ",
        "a             ##",
        "a #aaa#  #aaa###",
        "###   #aa#   ###"
      ],
      [
        "a              a",
        "a              a",
        "a             ##",
        "a             a ",
        "a             a ",
        "a             a ",
        "a             ##",
        "a              a",
        "a              a",
        "a             ##",
        "a             a ",
        "a             a ",
        "a             a ",
        "a             ##",
        "a #aaa#  #aaa###",
        "###   #aa#   ###"
      ],
      [
        "a              a",
        "a              a",
        "a             ##",
        "a             a ",
        "a             a ",
        "a             a ",
        "a             ##",
        "a              a",
        "a              a",
        "a             ##",
        "a             a ",
        "a             a ",
        "a             a ",
        "a             ##",
        "a #aaa#  #aaa###",
        "###   #aa#   ###"
      ]
    ]
  }]