[  {
    "type": "part",
    "name": "shopping11_2",
    "xsize": 16,
    "zsize": 16,
    "slices": [
      [
        "S$$SS$$SS$$SS$$Q",
        "$SS$$SS$$SS$$SSQ",
        "$SS$$SS$$SS$$SSQ",
        "S$$SS$$SS$$SS$$Q",
        "S$$SS$$SS$$SS$$Q",
        "$SS$$SS$$SS$$SSQ",
        "$SS$$SS$$SS$$SSQ",
        "S$$SS$$SS$$SS$$Q",
        "S$$SS$$SS$$SS$$Q",
        "$SS$$SS$$SS$$SSQ",
        "$SS$$SS$$SS$$SSQ",
        "S$$SS$$SS$$SS$$Q",
        "S$$SS$$SS$$SS$$Q",
        "$SS$$SS$$SS$$SSQ",
        "$SS$$SS$$SS$$SSQ",
        "$$$$$$$$$$$$$$$$"
      ],
      [
        ":              #",
        "               #",
        "               #",
        "               #",
        "               #",
        "               #",
        "               #",
        "               #",
        "       `))`    #",
        "       `  `    #",
        "       `  `    #",
        ":      `  `    #",
        ":      `  `    #",
        ":      `  `    #",
        ":              #",
        "################"
      ],
      [
        "               #",
        "               #",
        "               #",
        "               #",
        "               #",
        "               #",
        "               #",
        "               #",
        "       `  `    #",
        "       `))`    #",
        "       `       #",
        "       `       #",
        "       `       #",
        "       `       #",
        "               #",
        "################"
      ],
      [
        "               a",
        "               #",
        "               a",
        "               a",
        "               #",
        "               a",
        "               a",
        "              T#",
        "       `  `    a",
        "       `  `    a",
        "       `))`    #",
        "       `  `    a",
        "       `  `    a",
        "       `  `    #",
        "       T       #",
        "##aa#aa#aa#aa###"
      ],
      [
        "               #",
        "               #",
        "               #",
        "               #",
        "               #",
        "               #",
        "               #",
        "               #",
        "       `  `    #",
        "       `  `    #",
        "       `  `    #",
        "       `))`    #",
        "       `  `    #",
        "       `  `    #",
        "               #",
        "################"
      ],
      [
        "################",
        "################",
        "################",
        "################",
        "################",
        "################",
        "################",
        "################",
        "########  ######",
        "########  ######",
        "########  ######",
        "########  ######",
        "########))######",
        "################",
        "################",
        "################"
      ]
    ]
  }]