 [ {
    "type": "part",
    "name": "shopping_open10_1",
    "xsize": 16,
    "zsize": 16,
    "meta": [
      {
        "key": "dontconnect",
        "boolean": true
      }
    ],
    "slices": [
      [
        "###   #aa#   ###",
        "# #aaa#  #aaa###",
        "a             ##",
        "a             a ",
        "a             a ",
        "a             a ",
        "a             ##",
        "a              a",
        "a              a",
        "a             ##",
        "a             a ",
        "a             a ",
        "a             a ",
        "a             ##",
        "a              a",
        "a              a"
      ],
      [
        "###   #aa#   ###",
        "# #aaa#  #aaa###",
        "a             ##",
        "a             a ",
        "a             a ",
        "a             a ",
        "a             ##",
        "a              a",
        "a              a",
        "a             ##",
        "a             a ",
        "a             a ",
        "a             a ",
        "a             ##",
        "a              a",
        "a              a"
      ],
      [
        "###   #aa#   ###",
        "# #aaa#  #aaa###",
        "a             ##",
        "a             a ",
        "a             a ",
        "a             a ",
        "a             ##",
        "a              a",
        "a              a",
        "a             ##",
        "a             a ",
        "a             a ",
        "a             a ",
        "a             ##",
        "a              a",
        "a              a"
      ],
      [
        "###   #aa#   ###",
        "# #aaa#  #aaa###",
        "a             ##",
        "a             a ",
        "a             a ",
        "a             a ",
        "a             ##",
        "a              a",
        "a              a",
        "a             ##",
        "a             a ",
        "a             a ",
        "a             a ",
        "a             ##",
        "a              a",
        "a              a"
      ],
      [
        "###   ####   ###",
        "# #####  #######",
        "a             ##",
        "a             # ",
        "a             # ",
        "a             # ",
        "a             ##",
        "a              #",
        "a              #",
        "a             ##",
        "a             # ",
        "a             # ",
        "a             # ",
        "a             ##",
        "a              #",
        "a              #"
      ],
      [
        "################",
        "################",
        "a             ##",
        "a             ##",
        "a             ##",
        "a             ##",
        "a             ##",
        "a             ##",
        "a             ##",
        "a             ##",
        "a             ##",
        "a             ##",
        "a             ##",
        "a             ##",
        "a             ##",
        "a             ##"
      ]
    ]
  }]