[  {
    "type": "part",
    "name": "shopping_open10_2",
    "xsize": 16,
    "zsize": 16,
    "slices": [
      [
        "$$$$$$$$$$$$$$$$",
        "$SS$$SS$$SS$$SS$",
        "$SS$$SS$$SS$$SS$",
        "$$$SS$$SS$$SS$$$",
        "$$$SS$$SS$$SS$$$",
        "$SS$$SS$$SS$$SS$",
        "$SS$$SS$$SS$$SS$",
        "$$$SS$$SS$$SS$$$",
        "$$$SS$$SS$$SS$$$",
        "$SS$$SS$$SS$$SS$",
        "$SS$$SS$$SS$$SS$",
        "$$$SS$$SS$$SS$$$",
        "$$$SS$$SS$$SS$$$",
        "$SS$$SS$$SS$$SS$",
        "$SS$$SS$$SS$$SS$",
        "$$$SS$$SS$$SS$$$"
      ],
      [
        "################",
        "#              #",
        "a              #",
        "a              #",
        "a              #",
        "a              #",
        "a              #",
        "a              #",
        "a              #",
        "a              #",
        "a              #",
        "a              #",
        "a              #",
        "a              #",
        "a              #",
        "a              #"
      ],
      [
        "################",
        "#              #",
        "a              #",
        "a              #",
        "a              #",
        "a              #",
        "a              #",
        "a              #",
        "a              #",
        "a              #",
        "a              #",
        "a              #",
        "a              #",
        "a              #",
        "a              #",
        "a              #"
      ],
      [
        "##aa#aa#aa#aa###",
        "#      T       #",
        "a              #",
        "a              a",
        "a              a",
        "a              #",
        "a              a",
        "a              a",
        "a             T#",
        "a              a",
        "a              a",
        "a              #",
        "a              a",
        "a              a",
        "a              #",
        "a              a"
      ],
      [
        "################",
        "#              #",
        "a              #",
        "a              #",
        "a              #",
        "a              #",
        "a              #",
        "a              #",
        "a              #",
        "a              #",
        "a              #",
        "a              #",
        "a              #",
        "a              #",
        "a              #",
        "a              #"
      ],
      [
        "################",
        "################",
        "################",
        "################",
        "################",
        "################",
        "################",
        "################",
        "################",
        "################",
        "################",
        "################",
        "################",
        "################",
        "################",
        "################"
      ]
    ]
  }]