[  {
    "type": "part",
    "name": "stairsbig",
    "xsize": 6,
    "zsize": 12,
    "meta": [
      {
        "key": "z1",
        "integer": 4
      },
      {
        "key": "z2",
        "integer": 11
      }
    ],
    "slices": [
      [
        "      ",
        "      ",
        "      ",
        "      ",
        "xxxxxx",
        "xxxxx/",
        "xxxxx/",
        "xxxxx/",
        "xxxxx/",
        "xxxxx/",
        "xxxxx/",
        "xxxxxx"
      ],
      [
        "      ",
        "      ",
        "      ",
        "      ",
        "xxxxx_",
        "xxxx/ ",
        "xxxx/ ",
        "xxxx/ ",
        "xxxx/ ",
        "xxxx/ ",
        "xxxx/ ",
        "xxxxx_"
      ],
      [
        "      ",
        "      ",
        "      ",
        "      ",
        "xxxx_ ",
        "xxx/  ",
        "xxx/  ",
        "xxx/  ",
        "xxx/  ",
        "xxx/  ",
        "xxx/  ",
        "xxxx_ "
      ],
      [
        "      ",
        "      ",
        "      ",
        "      ",
        "xxx_  ",
        "xx/   ",
        "xx/   ",
        "xx/   ",
        "xx/   ",
        "xx/   ",
        "xx/   ",
        "xxx_  "
      ],
      [
        "      ",
        "      ",
        "      ",
        "      ",
        "xx_   ",
        "x/    ",
        "x/    ",
        "x/    ",
        "x/    ",
        "x/    ",
        "x/    ",
        "xx_   "
      ],
      [
        "      ",
        "      ",
        "      ",
        "      ",
        "x_    ",
        "/     ",
        "/     ",
        "/     ",
        "/     ",
        "/     ",
        "/     ",
        "x_    "
      ],
      [
        "      ",
        "      ",
        "      ",
        "      ",
        "_     ",
        "      ",
        "      ",
        "      ",
        "      ",
        "      ",
        "      ",
        "_     "
      ]
    ]
  }]