[
  {
    "type": "part",
    "name": "top_center_3",
    "xsize": 16,
    "zsize": 16,
    "slices": [
      [
        "################",
        "################",
        "################",
        "################",
        "################",
        "################",
        "################",
        "################",
        "################",
        "################",
        "################",
        "################",
        "################",
        "################",
        "################",
        "################"
      ],
      [
        "                ",
        "                ",
        "                ",
        "                ",
        "    #aaaaa#     ",
        "    a     a     ",
        "    a     a     ",
        "          a     ",
        "    a     a     ",
        "    a     a     ",
        "    #aaaaa#     ",
        "                ",
        "                ",
        "                ",
        "                ",
        "                "
      ],
      [
        "                ",
        "                ",
        "                ",
        "                ",
        "    #aaaaa#     ",
        "    a     a     ",
        "    a     a     ",
        "          a     ",
        "    a     a     ",
        "    a     a     ",
        "    #aaaaa#     ",
        "                ",
        "                ",
        "                ",
        "                ",
        "                "
      ],
      [
        "                ",
        "                ",
        "                ",
        "                ",
        "    #######     ",
        "    #######     ",
        "    #######     ",
        "    #######     ",
        "    #######     ",
        "    #######     ",
        "    #######     ",
        "                ",
        "                ",
        "                ",
        "                ",
        "                "
      ]
    ]
  }
]
