[
  {
    "type": "part",
    "name": "top_center00_1",
    "xsize": 16,
    "zsize": 16,
    "slices": [
      [
        "################",
        "################",
        "################",
        "################",
        "################",
        "################",
        "################",
        "################",
        "################",
        "################",
        "#############  #",
        "#############  #",
        "#############  #",
        "#############  #",
        "#############))#",
        "################"
      ]
    ]
  },
  {
    "type": "part",
    "name": "library01_3",
    "xsize": 16,
    "zsize": 16,
    "slices": [
      [
        "#SS#$$$$$$$$$$$$",
        "#SS#$$$$$$$$$$$$",
        "#SS#$$$$$$$$$$$$",
        "#SS#$$$$$$$$$$$$",
        "#SS#$$$$$$$$$$$$",
        "#SS#$$$$$$$$$$$$",
        "#SS#$$$$$$$$$$$$",
        "#SS#$$$$$$$$$$$$",
        "#SS#$$$$$$$$$$$$",
        "#SS#$$$$$$$$$$$$",
        "#SS#$$$$$$$$$$$$",
        "#SS#$$$$$$$$$$$$",
        "#SS#############",
        "#SSSSSSSSSSSSSSS",
        "#SSSSSSSSSSSSSSS",
        "################"
      ],
      [
        "a               ",
        "a               ",
        "a               ",
        "#               ",
        "a               ",
        "a               ",
        "a               ",
        "a               ",
        "###:::::::###   ",
        "a               ",
        "a   LLL     #   ",
        "a           :   ",
        "a   LLL     :   ",
        "#           #   ",
        "a F         #   ",
        "aa#aaaa#aaaa#aaa"
      ],
      [
        "a               ",
        "a               ",
        "a               ",
        "#               ",
        "a               ",
        "a               ",
        "a               ",
        "a               ",
        "###:::::::###   ",
        "a               ",
        "a   LLL     #   ",
        "a           :   ",
        "a   LLLT    :   ",
        "#           #   ",
        "a           #   ",
        "aa#aaaa#aaaa#aaa"
      ],
      [
        "a               ",
        "a               ",
        "a               ",
        "#               ",
        "a               ",
        "a               ",
        "a               ",
        "a               ",
        "###:::::::###   ",
        "a           #   ",
        "a   LLL     #   ",
        "a           :   ",
        "a   LLL     :   ",
        "#           #   ",
        "a           #   ",
        "aa#aaaa#aaaa#aaa"
      ],
      [
        "#               ",
        "#               ",
        "#               ",
        "#               ",
        "#               ",
        "#               ",
        "#               ",
        "#               ",
        "###:::::::###   ",
        "#           #   ",
        "#           #   ",
        "#           :   ",
        "#           :   ",
        "#           #   ",
        "#           #   ",
        "################"
      ],
      [
        "################",
        "################",
        "################",
        "################",
        "################",
        "################",
        "################",
        "################",
        "################",
        "################",
        "################",
        "################",
        "################",
        "################",
        "################",
        "################"
      ]
    ]
  }
]
