[
	{
		"type": "part",
		"name": "top_library_4",
		"xsize": 16,
		"zsize": 16,
		"slices": [
			[
				"################",
				"################",
				"################",
				"################",
				"################",
				"################",
				"################",
				"################",
				"################",
				"################",
				"################",
				"################",
				"################",
				"################",
				"################",
				"################"
			],
			[
				"################",
				"#DDDDDDDDDDDDDD#",
				"#DGGDDDDDDDDDDD#",
				"#DDDDDDDDDDGDDD#",
				"#DDDDDDDDDDDDDD#",
				"#DDDGDDDDDDDDDD#",
				"#DDDDDDDGDDDDDD#",
				"#DDDDDDDDDDDDDD#",
				"#DDDGDDDDGDDDDD#",
				"#DDDDDDDDDDDDDD#",
				"#DDDDGDDDDDDGDD#",
				"#DDDDDDDDDGDDDD#",
				"#DDDDDGDDDDDDDD#",
				"#DDDDDDDDDGDDDD#",
				"#DDDGDDDDDDDDDD#",
				"################"
			],
			[
				"            p   ",
				"                ",
				" p    p         ",
				"           p    ",
				"    p           ",
				"         p      ",
				"                ",
				"                ",
				"    p        p  ",
				"                ",
				"                ",
				"        p       ",
				"                ",
				"   p            ",
				"                ",
				"           p    "
			]
		]
	}
]