[
	{
		"type": "part",
		"name": "top_library00_2",
		"xsize": 16,
		"zsize": 16,
		"slices": [
			[
				"################",
				"################",
				"################",
				"################",
				"################",
				"################",
				"################",
				"################",
				"################",
				"################",
				"#############  #",
				"#############  #",
				"#############  #",
				"#############  #",
				"#############))#",
				"################"
			],
			[
				"wwwwwwwwwwwwwwww",
				"w              w",
				"w              w",
				"w              w",
				"w              w",
				"w              w",
				"w               ",
				"w               ",
				"w               ",
				"w           w  w",
				"w              w",
				"w              w",
				"w              w",
				"w              w",
				"w              w",
				"wwwwwwww    wwww"
			],
			[
				"                ",
				"                ",
				"                ",
				"                ",
				"                ",
				"                ",
				"                ",
				"                ",
				"                ",
				"            w  w",
				"                ",
				"                ",
				"                ",
				"                ",
				"                ",
				"            w  w"
			],
			[
				"                ",
				"                ",
				"                ",
				"                ",
				"                ",
				"                ",
				"                ",
				"                ",
				"                ",
				"            ####",
				"            ####",
				"            ####",
				"            ####",
				"            ####",
				"            ####",
				"            ####"
			]
		]
	}
]