 [ {
    "type": "part",
    "name": "town01_0",
    "xsize": 16,
    "zsize": 16,
    "slices": [
      [
        "##S$S$S$S$S$S$SQ",
        "#S$S$S$S$S$S$S$S",
        "#$S$S$S$S$S$S$SQ",
        "#S$S$S$S$S$S$S$S",
        "#$S$S$S$S$S$S$SQ",
        "#S$S$S$S$S$S$S$S",
        "#$S$S$S$S$S$S$SQ",
        "#S$S$S$S$S$S$S$S",
        "#$S$S$S$S$S$S$SQ",
        "#S$S$S$S$S$S$S$S",
        "#$S$S$S$S$S$S$SQ",
        "#S$S$S$S$S$S$S$S",
        "#$S$S$S$S$S$S$SQ",
        "#S$S$S$S$S$S$S$S",
        "##S$S$S$S$S$S$S#",
        "################"
      ],
      [
        "##              ",
        "a               ",
        "a               ",
        "a               ",
        "a               ",
        "a               ",
        "a               ",
        "a       T       ",
        "a               ",
        "a               ",
        "a               ",
        "a               ",
        "a               ",
        "a               ",
        "##             #",
        "##aaaaaaaaaaaaa#"
      ],
      [
        "##              ",
        "a               ",
        "a               ",
        "a               ",
        "a               ",
        "a               ",
        "a               ",
        "a               ",
        "a               ",
        "a               ",
        "a               ",
        "a               ",
        "a               ",
        "a               ",
        "##             #",
        "##aaaaaaaaaaaaa#"
      ],
      [
        "##              ",
        "a               ",
        "a               ",
        "a               ",
        "a               ",
        "a               ",
        "a               ",
        "a               ",
        "a               ",
        "a               ",
        "a               ",
        "a               ",
        "a               ",
        "a               ",
        "##             #",
        "##aaaaaaaaaaaaa#"
      ],
      [
        "##              ",
        "a               ",
        "a               ",
        "a               ",
        "a               ",
        "a               ",
        "a               ",
        "a               ",
        "a               ",
        "a               ",
        "a               ",
        "a               ",
        "a               ",
        "a               ",
        "##             #",
        "##aaaaaaaaaaaaa#"
      ],
      [
        "################",
        "################",
        "################",
        "################",
        "################",
        "################",
        "################",
        "################",
        "################",
        "################",
        "################",
        "################",
        "################",
        "################",
        "################",
        "################"
      ]
    ]
  }]