[  {
    "type": "part",
    "name": "town00_c",
    "xsize": 16,
    "zsize": 16,
    "slices": [
      [
        "################",
        "##$S$S$S$S$S$SQ#",
        "#$S$S$S$S$S$S$SQ",
        "#S$S$S$S$S$S$S$S",
        "#$S$S$S$S$S$S$SQ",
        "#S$S$S$S$S$S$S$S",
        "#$S$S$S$S$S$S$SQ",
        "#S$S$S$S$S$S$S$S",
        "#$S$S$S$S$S$S$SQ",
        "#S$S$S$S$S$S$S$S",
        "#$S$S$S$S$S$S  Q",
        "#S$S$S$S$S$SQ  S",
        "#$S$S$S$S$S$S  Q",
        "#S$S$S$S$S$SQ  S",
        "#$S$S$S$S$S$S))Q",
        "##$S$S$S$S$S$S$S"
      ],
      [
        "##::#########::#",
        "##             #",
        ":               ",
        ":               ",
        "#               ",
        "#               ",
        "#               ",
        "#               ",
        "#               ",
        "#            )) ",
        "#           Q  Q",
        "#           Q  Q",
        "#           Q  Q",
        ":           Q  Q",
        ":           Q  Q",
        "##              "
      ],
      [
        "##::#########::#",
        "##             #",
        ":               ",
        ":               ",
        "#               ",
        "#               ",
        "#               ",
        "#               ",
        "#               ",
        "#               ",
        "#           a))a",
        "#           a  a",
        "#           a  a",
        ":           a  a",
        ":           a  a",
        "##              "
      ],
      [
        "##::#########::#",
        "##             #",
        ":               ",
        ":               ",
        "#               ",
        "#               ",
        "#               ",
        "#               ",
        "#               ",
        "#               ",
        "#           a  a",
        "#           a))a",
        "#           a  a",
        ":           a  a",
        ":           a  a",
        "##              "
      ],
      [
        "##::#########::#",
        "##             #",
        ":               ",
        ":               ",
        "#               ",
        "#               ",
        "#               ",
        "#               ",
        "#               ",
        "#               ",
        "#           a  a",
        "#           a  a",
        "#           a))a",
        ":           a  a",
        ":           a  a",
        "##              "
      ],
      [
        "################",
        "################",
        "################",
        "################",
        "################",
        "################",
        "################",
        "################",
        "################",
        "################",
        "#############  #",
        "#############  #",
        "#############  #",
        "#############))#",
        "#############  #",
        "################"
      ]
    ]
  }]