[  {
    "type": "part",
    "name": "town00_0",
    "xsize": 16,
    "zsize": 16,
    "slices": [
      [
        "################",
        "##$S$S$S$S$S$SQ#",
        "#$S$S$S$S$S$S$SQ",
        "#S$S$S$S$S$S$S$S",
        "#$S$S$S$S$S$S$SQ",
        "#S$S$S$S$S$S$S$S",
        "#$S$S$S$S$S$S$SQ",
        "#S$S$S$S$S$S$S$S",
        "#$S$S$S$S$S$S$SQ",
        "#S$S$S$S$S$S$S$S",
        "#$S$S$S$S$S$S  Q",
        "#S$S$S$S$S$SQ  S",
        "#$S$S$S$S$S$S  Q",
        "#S$S$S$S$S$SQ  S",
        "#$S$S$S$S$S$S))Q",
        "##$S$S$S$S$S$S$S"
      ],
      [
        "##aaaaaaaaaaaaa#",
        "##             #",
        "a               ",
        "a               ",
        "a               ",
        "a               ",
        "a               ",
        "a               ",
        "a               ",
        "a            )) ",
        "a           Q  Q",
        "a           Q  Q",
        "a           Q  Q",
        "a           Q  Q",
        "a           Q  Q",
        "##              "
      ],
      [
        "##aaaaaaaaaaaaa#",
        "##             #",
        "a               ",
        "a               ",
        "a               ",
        "a               ",
        "a               ",
        "a               ",
        "a               ",
        "a               ",
        "a           a))a",
        "a           a  a",
        "a           a  a",
        "a           a  a",
        "a           a  a",
        "##              "
      ],
      [
        "##aaaaaaaaaaaaa#",
        "##             #",
        "a               ",
        "a               ",
        "a               ",
        "a               ",
        "a               ",
        "a               ",
        "a               ",
        "a               ",
        "a           a  a",
        "a           a))a",
        "a           a  a",
        "a           a  a",
        "a           a  a",
        "##              "
      ],
      [
        "##aaaaaaaaaaaaa#",
        "##             #",
        "a               ",
        "a               ",
        "a               ",
        "a               ",
        "a               ",
        "a               ",
        "a               ",
        "a               ",
        "a           a  a",
        "a           a  a",
        "a           a))a",
        "a           a  a",
        "a           a  a",
        "##              "
      ],
      [
        "################",
        "################",
        "################",
        "################",
        "################",
        "################",
        "################",
        "################",
        "################",
        "################",
        "#############  #",
        "#############  #",
        "#############  #",
        "#############))#",
        "#############  #",
        "################"
      ]
    ]
  }]