[  {
    "type": "part",
    "name": "town10_1",
    "xsize": 16,
    "zsize": 16,
    "slices": [
      [
        "##::#aaaaaa#::##",
        "#####S$S$SQ#####",
        "S$S$S$S$S$S$SQ#:",
        "$S$S$S$S$S$S$S#:",
        "S$S$S$S$S$S$SQ##",
        "$S$S$S$S$S$S$SQa",
        "S$S$S$S$S$S$S$Sa",
        "$S$S$S$S$S$S$SQa",
        "S$S$S$S$S$S$S$Sa",
        "$S$S$S$S$S$S$SQa",
        "S$S$S$S$S$S$S$Sa",
        "$S$S$S$S$S$S$S##",
        "S$S$S$S$S$S$SQ#:",
        "$S$S$S$S$S$S$S#:",
        "S$S$S$S$S$S$SQ##",
        "$S$S$S$S$S$S$S##"
      ],
      [
        "##::#aaaaaa#::##",
        "##aa#      #aa##",
        "              a:",
        "              a:",
        "              ##",
        "               a",
        "               a",
        "               a",
        "               a",
        "               a",
        "               a",
        "              ##",
        "              a:",
        "              a:",
        "              ##",
        "              ##"
      ],
      [
        "##::#aaaaaa#::##",
        "##aa#      #aa##",
        "              a:",
        "              a:",
        "              ##",
        "               a",
        "               a",
        "               a",
        "               a",
        "               a",
        "               a",
        "              ##",
        "              a:",
        "              a:",
        "              ##",
        "              ##"
      ],
      [
        "##::#aaaaaa#::##",
        "##aa#      #aa##",
        "              a:",
        "              a:",
        "              ##",
        "               a",
        "               a",
        "               a",
        "               a",
        "               a",
        "               a",
        "              ##",
        "              a:",
        "              a:",
        "              ##",
        "              ##"
      ],
      [
        "##::#aaaaaa#::##",
        "##aa#      #aa##",
        "              a:",
        "              a:",
        "              ##",
        "               a",
        "               a",
        "               a",
        "               a",
        "               a",
        "               a",
        "              ##",
        "              a:",
        "              a:",
        "              ##",
        "              ##"
      ],
      [
        "##::#aaaaaa#::##",
        "################",
        "###############:",
        "###############:",
        "################",
        "###############a",
        "###############a",
        "###############a",
        "###############a",
        "###############a",
        "###############a",
        "################",
        "###############:",
        "###############:",
        "################",
        "################"
      ]
    ]
  }]