[  {
    "type": "part",
    "name": "town11_c",
    "xsize": 16,
    "zsize": 16,
    "slices": [
      [
        "S$S$S$S$S$S$SQ##",
        "$S$S$S$S$S$S$SQ#",
        "S$S$S$S$S$S$S$S#",
        "$S$S$S$S$S$S$SQ#",
        "S$S$S$S$S$S$S$S#",
        "$S$S$S$S$S$S$SQ#",
        "S$S$S$S$S$S$S$S#",
        "$S$S$S$S$S$S$SQ#",
        "S$S$S$S$S$S$S$S#",
        "$S$S$S$S$S$S$SQ#",
        "S$S$S$S$S$S$S$S#",
        "$S$S$S$S$S$S$SQ#",
        "S$S$S$S$S$S$S$S#",
        "$S$S$S$S$S$S$SQ#",
        "#$S$S$S$S$S$SQ##",
        "################"
      ],
      [
        "              ##",
        "               :",
        "               :",
        "               #",
        "               #",
        "               #",
        "               #",
        "               #",
        "               #",
        "               #",
        "               #",
        "               #",
        "               :",
        "               :",
        "#             ##",
        "#::#########::##"
      ],
      [
        "              ##",
        "               :",
        "               :",
        "               #",
        "               #",
        "               #",
        "               #",
        "               #",
        "               #",
        "               #",
        "               #",
        "               #",
        "               :",
        "               :",
        "#             ##",
        "#::#########::##"
      ],
      [
        "              ##",
        "               :",
        "               :",
        "               #",
        "               #",
        "               #",
        "               #",
        "               #",
        "               #",
        "               #",
        "               #",
        "               #",
        "               :",
        "               :",
        "#             ##",
        "#::#########::##"
      ],
      [
        "              ##",
        "               :",
        "               :",
        "               #",
        "               #",
        "               #",
        "               #",
        "               #",
        "               #",
        "               #",
        "               #",
        "               #",
        "               :",
        "               :",
        "#             ##",
        "#::#########::##"
      ],
      [
        "################",
        "################",
        "################",
        "################",
        "################",
        "################",
        "################",
        "################",
        "################",
        "################",
        "################",
        "################",
        "################",
        "################",
        "################",
        "################"
      ]
    ]
  }]