[  {
    "type": "part",
    "name": "town11_1",
    "xsize": 16,
    "zsize": 16,
    "slices": [
      [
        "S$S$S$S$S$S$SQ##",
        "$S$S$S$S$S$S$S##",
        "S$S$S$S$S$S$SQ#:",
        "$S$S$S$S$S$S$S#:",
        "S$S$S$S$S$S$SQ##",
        "$S$S$S$S$S$S$SQa",
        "S$S$S$S$S$S$S$Sa",
        "$S$S$S$S$S$S$SQa",
        "S$S$S$S$S$S$S$Sa",
        "$S$S$S$S$S$S$SQa",
        "S$S$S$S$S$S$S$Sa",
        "$S$S$S$S$S$S$S##",
        "S$S$S$S$S$S$SQ#:",
        "$S$S$S$S$S$S$S#:",
        "#####$S$S$S#####",
        "##::#aaaaaa#::##"
      ],
      [
        "              ##",
        "              ##",
        "              a:",
        "              a:",
        "              ##",
        "               a",
        "               a",
        "               a",
        "               a",
        "               a",
        "               a",
        "              ##",
        "              a:",
        "              a:",
        "##aa#      #aa##",
        "##::#aaaaaa#::##"
      ],
      [
        "              ##",
        "              ##",
        "              a:",
        "              a:",
        "              ##",
        "               a",
        "               a",
        "               a",
        "               a",
        "               a",
        "               a",
        "              ##",
        "              a:",
        "              a:",
        "##aa#      #aa##",
        "##::#aaaaaa#::##"
      ],
      [
        "              ##",
        "              ##",
        "              a:",
        "              a:",
        "              ##",
        "               a",
        "               a",
        "               a",
        "               a",
        "               a",
        "               a",
        "              ##",
        "              a:",
        "              a:",
        "##aa#      #aa##",
        "##::#aaaaaa#::##"
      ],
      [
        "              ##",
        "              ##",
        "              a:",
        "              a:",
        "              ##",
        "               a",
        "               a",
        "               a",
        "               a",
        "               a",
        "               a",
        "              ##",
        "              a:",
        "              a:",
        "##aa#      #aa##",
        "##::#aaaaaa#::##"
      ],
      [
        "################",
        "################",
        "###############:",
        "###############:",
        "################",
        "###############a",
        "###############a",
        "###############a",
        "###############a",
        "###############a",
        "###############a",
        "################",
        "###############:",
        "###############:",
        "################",
        "##::#aaaaaa#::##"
      ]
    ]
  }]