[  
  {
    "type": "part",
    "name": "town_in_2",
    "xsize": 16,
    "zsize": 16,
    "slices": [
      [
        "                ",
        "                ",
        "                ",
        "                ",
        "                ",
        "                ",
        "                ",
        "                ",
        "                ",
        "                ",
        "                ",
        "                ",
        "                ",
        "                ",
        "                ",
        "                "
      ],
      [
        "                ",
        "                ",
        "                ",
        "   ##########   ",
        "   #1      1#   ",
        "   #    !!  #   ",
        "   #  ##### #   ",
        "   # !#     #   ",
        "   # !# ### #   ",
        "   #  # #4  #   ",
        "   #  # #   #   ",
        "   # 1# #C  #   ",
        "   #### #####   ",
        "                ",
        "                ",
        "                "
      ],
      [
        "                ",
        "                ",
        "                ",
        "   ##########   ",
        "   #        #   ",
        "   #        #   ",
        "   #  ##### #   ",
        "   #  #     #   ",
        "   #  # ### #   ",
        "   #  # #   #   ",
        "   #  # #   #   ",
        "   #  # #   #   ",
        "   #### #####   ",
        "                ",
        "                ",
        "                "
      ],
      [
        "                ",
        "                ",
        "                ",
        "   ##########   ",
        "   #        #   ",
        "   #        #   ",
        "   #  ##### #   ",
        "   #  #     #   ",
        "   #  # ### #   ",
        "   #  # #   #   ",
        "   #  # #   #   ",
        "   #  # #   #   ",
        "   ##########   ",
        "                ",
        "                ",
        "                "
      ],
      [
        "                ",
        "                ",
        "                ",
        "   ##########   ",
        "   #        #   ",
        "   #        #   ",
        "   #  ##### #   ",
        "   #  #     #   ",
        "   #  # ### #   ",
        "   #  # #   #   ",
        "   #  # #   #   ",
        "   #  # #   #   ",
        "   ##########   ",
        "                ",
        "                ",
        "                "
      ]
    ]
  }]