[  {
    "type": "part",
    "name": "town01_1",
    "xsize": 16,
    "zsize": 16,
    "slices": [
      [
        "##S$S$S$S$S$S$SQ",
        "##$S$S$S$S$S$S$S",
        ":#S$S$S$S$S$S$SQ",
        ":#$S$S$S$S$S$S$S",
        "##S$S$S$S$S$S$SQ",
        "aS$S$S$S$S$S$S$S",
        "a$S$S$S$S$S$S$SQ",
        "aS$S$S$S$S$S$S$S",
        "a$S$S$S$S$S$S$SQ",
        "aS$S$S$S$S$S$S$S",
        "a$S$S$S$S$S$S$SQ",
        "##$S$S$S$S$S$S$S",
        ":#S$S$S$S$S$S$SQ",
        ":#$S$S$S$S$S$S$S",
        "#####$S$S$S#####",
        "##::#aaaaaa#::##"
      ],
      [
        "##              ",
        "##              ",
        ":a              ",
        ":a              ",
        "##              ",
        "a               ",
        "a               ",
        "a       T       ",
        "a               ",
        "a               ",
        "a               ",
        "##              ",
        ":a              ",
        ":a              ",
        "##aa#      #aa##",
        "##::#aaaaaa#::##"
      ],
      [
        "##              ",
        "##              ",
        ":a              ",
        ":a              ",
        "##              ",
        "a               ",
        "a               ",
        "a               ",
        "a               ",
        "a               ",
        "a               ",
        "##              ",
        ":a              ",
        ":a              ",
        "##aa#      #aa##",
        "##::#aaaaaa#::##"
      ],
      [
        "##              ",
        "##              ",
        ":a              ",
        ":a              ",
        "##              ",
        "a               ",
        "a               ",
        "a               ",
        "a               ",
        "a               ",
        "a               ",
        "##              ",
        ":a              ",
        ":a              ",
        "##aa#      #aa##",
        "##::#aaaaaa#::##"
      ],
      [
        "##              ",
        "##              ",
        ":a              ",
        ":a              ",
        "##              ",
        "a               ",
        "a               ",
        "a               ",
        "a               ",
        "a               ",
        "a               ",
        "##              ",
        ":a              ",
        ":a              ",
        "##aa#      #aa##",
        "##::#aaaaaa#::##"
      ],
      [
        "################",
        "################",
        ":###############",
        ":###############",
        "################",
        "a###############",
        "a###############",
        "a###############",
        "a###############",
        "a###############",
        "a###############",
        "################",
        ":###############",
        ":###############",
        "################",
        "##::#aaaaaa#::##"
      ]
    ]
  }]