[  {
    "type": "part",
    "name": "town11_0",
    "xsize": 16,
    "zsize": 16,
    "slices": [
      [
        "S$S$S$S$S$S$SQ##",
        "$S$S$S$S$S$S$SQ#",
        "S$S$S$S$S$S$S$S#",
        "$S$S$S$S$S$S$SQ#",
        "S$S$S$S$S$S$S$S#",
        "$S$S$S$S$S$S$SQ#",
        "S$S$S$S$S$S$S$S#",
        "$S$S$S$S$S$S$SQ#",
        "S$S$S$S$S$S$S$S#",
        "$S$S$S$S$S$S$SQ#",
        "S$S$S$S$S$S$S$S#",
        "$S$S$S$S$S$S$SQ#",
        "S$S$S$S$S$S$S$S#",
        "$S$S$S$S$S$S$SQ#",
        "#$S$S$S$S$S$SQ##",
        "################"
      ],
      [
        "              ##",
        "               a",
        "               a",
        "               a",
        "               a",
        "               a",
        "               a",
        "               a",
        "               a",
        "               a",
        "               a",
        "               a",
        "               a",
        "               a",
        "#             ##",
        "#aaaaaaaaaaaaa##"
      ],
      [
        "              ##",
        "               a",
        "               a",
        "               a",
        "               a",
        "               a",
        "               a",
        "               a",
        "               a",
        "               a",
        "               a",
        "               a",
        "               a",
        "               a",
        "#             ##",
        "#aaaaaaaaaaaaa##"
      ],
      [
        "              ##",
        "               a",
        "               a",
        "               a",
        "               a",
        "               a",
        "               a",
        "               a",
        "               a",
        "               a",
        "               a",
        "               a",
        "               a",
        "               a",
        "#             ##",
        "#aaaaaaaaaaaaa##"
      ],
      [
        "              ##",
        "               a",
        "               a",
        "               a",
        "               a",
        "               a",
        "               a",
        "               a",
        "               a",
        "               a",
        "               a",
        "               a",
        "               a",
        "               a",
        "#             ##",
        "#aaaaaaaaaaaa:##"
      ],
      [
        "################",
        "################",
        "################",
        "################",
        "################",
        "################",
        "################",
        "################",
        "################",
        "################",
        "################",
        "################",
        "################",
        "################",
        "################",
        "################"
      ]
    ]
  }]