 [ {
    "type": "part",
    "name": "town_in_3",
    "xsize": 16,
    "zsize": 16,
    "slices": [
      [
        "                ",
        "                ",
        "                ",
        "                ",
        "                ",
        "                ",
        "                ",
        "                ",
        "                ",
        "                ",
        "                ",
        "                ",
        "                ",
        "                ",
        "                ",
        "                "
      ],
      [
        "                ",
        "                ",
        "   ##########   ",
        "   #        #   ",
        "   #        #   ",
        "   #  ##### #   ",
        "   #  #     #   ",
        "   #  # ### #   ",
        "   #  # #   #   ",
        "   #  # #   #   ",
        "   # 1# #1  #   ",
        "   #### #####   ",
        "                ",
        "                ",
        "                ",
        "                "
      ],
      [
        "                ",
        "                ",
        "   ##########   ",
        "   #        #   ",
        "   #        #   ",
        "   #  ##### #   ",
        "   #  #     #   ",
        "   #  # ### #   ",
        "   #  # #   #   ",
        "   #  # #   #   ",
        "   #  # #   #   ",
        "   #### #####   ",
        "                ",
        "                ",
        "                ",
        "                "
      ],
      [
        "                ",
        "                ",
        "   ##########   ",
        "   #        #   ",
        "   #        #   ",
        "   #  ##### #   ",
        "   #  #     #   ",
        "   #  # ### #   ",
        "   #  # #   #   ",
        "   #  # #   #   ",
        "   #  # #   #   ",
        "   ##########   ",
        "                ",
        "                ",
        "                ",
        "                "
      ],
      [
        "                ",
        "                ",
        "   ##########   ",
        "   #        #   ",
        "   #        #   ",
        "   #  ##### #   ",
        "   #  #     #   ",
        "   #  # ### #   ",
        "   #  # #   #   ",
        "   #  # #   #   ",
        "   #  # #   #   ",
        "   ##########   ",
        "                ",
        "                ",
        "                ",
        "                "
      ]
    ]
  }]