[  {
    "type": "part",
    "name": "town00_1",
    "xsize": 16,
    "zsize": 16,
    "slices": [
      [
        "##::#aaaaaa#::##",
        "#####S$S$SQ#####",
        ":#S$S$S$S$S$S$SQ",
        ":#$S$S$S$S$S$S$S",
        "##S$S$S$S$S$S$SQ",
        "aS$S$S$S$S$S$S$S",
        "a$S$S$S$S$S$S$SQ",
        "aS$S$S$S$S$S$S$S",
        "a$S$S$S$S$S$S$SQ",
        "aS$S$S$S$S$S$S$S",
        "a$S$S$S$S$S$S  Q",
        "##$S$S$S$S$SQ  S",
        ":#S$S$S$S$S$S  Q",
        ":#$S$S$S$S$SQ  S",
        "##S$S$S$S$S$S))Q",
        "##$S$S$S$S$S$S$S"
      ],
      [
        "##::#aaaaaa#::##",
        "##aa#      #aa##",
        ":a              ",
        ":a              ",
        "##              ",
        "a               ",
        "a               ",
        "a               ",
        "a               ",
        "a            )) ",
        "a           Q  Q",
        "##          Q  Q",
        ":a          Q  Q",
        ":a          Q  Q",
        "##          Q  Q",
        "##              "
      ],
      [
        "##::#aaaaaa#::##",
        "##aa#      #aa##",
        ":a              ",
        ":a              ",
        "##              ",
        "a               ",
        "a               ",
        "a               ",
        "a               ",
        "a               ",
        "a           a))a",
        "##          a  a",
        ":a          a  a",
        ":a          a  a",
        "##          a  a",
        "##              "
      ],
      [
        "##::#aaaaaa#::##",
        "##aa#      #aa##",
        ":a              ",
        ":a              ",
        "##              ",
        "a               ",
        "a               ",
        "a               ",
        "a               ",
        "a               ",
        "a           a  a",
        "##          a))a",
        ":a          a  a",
        ":a          a  a",
        "##          a  a",
        "##              "
      ],
      [
        "##::#aaaaaa#::##",
        "##aa#      #aa##",
        ":a              ",
        ":a              ",
        "##              ",
        "a               ",
        "a               ",
        "a               ",
        "a               ",
        "a               ",
        "a           a  a",
        "##          a  a",
        ":a          a))a",
        ":a          a  a",
        "##          a  a",
        "##              "
      ],
      [
        "##::#aaaaaa#::##",
        "################",
        ":###############",
        ":###############",
        "################",
        "a###############",
        "a###############",
        "a###############",
        "a###############",
        "a###############",
        "a############  #",
        "#############  #",
        ":############  #",
        ":############))#",
        "#############  #",
        "################"
      ]
    ]
  }]