[  {
    "type": "part",
    "name": "town01_c",
    "xsize": 16,
    "zsize": 16,
    "slices": [
      [
        "##S$S$S$S$S$S$SQ",
        "#S$S$S$S$S$S$S$S",
        "#$S$S$S$S$S$S$SQ",
        "#S$S$S$S$S$S$S$S",
        "#$S$S$S$S$S$S$SQ",
        "#S$S$S$S$S$S$S$S",
        "#$S$S$S$S$S$S$SQ",
        "#S$S$S$S$S$S$S$S",
        "#$S$S$S$S$S$S$SQ",
        "#S$S$S$S$S$S$S$S",
        "#$S$S$S$S$S$S$SQ",
        "#S$S$S$S$S$S$S$S",
        "#$S$S$S$S$S$S$SQ",
        "#S$S$S$S$S$S$S$S",
        "##S$S$S$S$S$S$S#",
        "################"
      ],
      [
        "##              ",
        ":               ",
        ":               ",
        "#               ",
        "#               ",
        "#               ",
        "#               ",
        "#       T       ",
        "#               ",
        "#               ",
        "#               ",
        "#               ",
        ":               ",
        ":               ",
        "##             #",
        "##::#########::#"
      ],
      [
        "##              ",
        ":               ",
        ":               ",
        "#               ",
        "#               ",
        "#               ",
        "#               ",
        "#               ",
        "#               ",
        "#               ",
        "#               ",
        "#               ",
        ":               ",
        ":               ",
        "##             #",
        "##::#########::#"
      ],
      [
        "##              ",
        ":               ",
        ":               ",
        "#               ",
        "#               ",
        "#               ",
        "#               ",
        "#               ",
        "#               ",
        "#               ",
        "#               ",
        "#               ",
        ":               ",
        ":               ",
        "##             #",
        "##::#########::#"
      ],
      [
        "##              ",
        ":               ",
        ":               ",
        "#               ",
        "#               ",
        "#               ",
        "#               ",
        "#               ",
        "#               ",
        "#               ",
        "#               ",
        "#               ",
        ":               ",
        ":               ",
        "##             #",
        "##::#########::#"
      ],
      [
        "################",
        "################",
        "################",
        "################",
        "################",
        "################",
        "################",
        "################",
        "################",
        "################",
        "################",
        "################",
        "################",
        "################",
        "################",
        "################"
      ]
    ]
  }]